Workbook

Sheet 总表
A1: 商品编码 | B1: PT品牌asin | C1: 平台商品编码 | D1: 发货方式 | E1: 平台SKU状态 | F1: 新/老品 | G1: q2 bcg（asin） | H1: q3 bcg（asin） | I1: q2 bcg（商编维度） | J1: 当前界面list price | K1: 红线价 | L1: 中心价 | M1: 价格下限 | N1: 价格上限 | O1: 4月销量 | P1: 5月销量 | Q1: 6月销量 | R1: 7月销量 | S1: 8月销量 | T1: 9月销量 | U1: 10月销量（截至10.14） | V1: Q2毛利率 | W1: Q3毛利率 | X1: 9月毛利率 | Y1: 9月退款率 | Z1: 9月广告费率 | AA1: 9月促销费率 | AB1: 9月转化率 | AC1: 9月广告转化率 | AD1: FBA可用 | AE1: FBA可售 | AF1: FBA在途 | AG1: 海外仓可用库存 | AH1: 海外仓在途库存 | AI1: Q2市场月均销量 | AJ1: Q3市场月均销量 | AK1: Q2月均销量 | AL1: Q3月均销量 | AM1: PT Q2asin市占 | AN1: PT Q3asin市占
A2: OO2EWP09900 | B2: B0G3LJ7K3X | C2: 3459EWP099NUS | D2: FBA | E2: 维稳 | F2: 老品 | G2: 瘦狗 | H2: 明星 | I2: 潜力 | J2: 29.99 | K2: 22.77 | L2: 34.8 | M2: 31.32 | N2: 38.29 | O2: 0 | P2: 0 | Q2: 0 | R2: 10 | S2: 11 | T2: 17 | U2: 6 | V2: 0 | W2: 0.20017386 | X2: 0.18910482 | Y2: 0.11111111 | Z2: 0.040013338 | AA2: 0.058284152 | AB2: 0.17346939 | AC2: 0.11077784 | AD2: =VLOOKUP(B:B,库存明细报表10.16!L:P,5,0) -> 2 | AE2: =VLOOKUP(B:B,库存明细报表10.16!L:Q,6,0) -> 0 | AF2: =VLOOKUP(B:B,库存明细报表10.16!L:T,9,0) -> 1 | AG2: =VLOOKUP(A:A,进销存报表10.16!A:J,10,0) -> 21 | AH2: =VLOOKUP(A:A,进销存报表10.16!A:K,11,0) -> 37 | AI2: 140.87 | AJ2: 126.03 | AK2: 0 | AL2: 13.333333 | AM2: =AK2/AI2 -> 0 | AN2: =AL2/AJ2 -> 0.10579492
A3: OO2EWP10100 | B3: B0GWQLK91B | C3: 8230EWP101JUS | D3: FBA | E3: 维稳 | F3: 老品 | G3: 瘦狗 | H3: 明星 | I3: 潜力 | J3: 49.99 | K3: 40.12 | L3: 45.58 | M3: 41.02 | N3: 50.14 | O3: 0 | P3: 0 | Q3: 0 | R3: 8 | S3: 1 | T3: 2 | U3: 2 | V3: 0 | W3: 0.21656093 | X3: 0.18368618 | Y3: 0 | Z3: 0.033706741 | AA3: 0.043829522 | AB3: 0.125 | AC3: 0 | AD3: =VLOOKUP(B:B,库存明细报表10.16!L:P,5,0) -> 4 | AE3: =VLOOKUP(B:B,库存明细报表10.16!L:Q,6,0) -> 4 | AF3: =VLOOKUP(B:B,库存明细报表10.16!L:T,9,0) -> 0 | AG3: =VLOOKUP(A:A,进销存报表10.16!A:J,10,0) -> 12 | AH3: =VLOOKUP(A:A,进销存报表10.16!A:K,11,0) -> 6 | AI3: 42.2 | AJ3: 32.83 | AK3: 0 | AL3: 3.6666667 | AM3: =AK3/AI3 -> 0 | AN3: =AL3/AJ3 -> 0.11168647
A4: OO2EWP11800 | B4: B0GWQVWRRZ | C4: 3194EWP118ZUS | D4: FBA | E4: 风险 | F4: 老品 | G4: 瘦狗 | H4: 金牛 | I4: 瘦狗 | J4: 27.99 | K4: 19.63 | L4: 27.66 | M4: 24.89 | N4: 30.42 | O4: 0 | P4: 0 | Q4: 0 | R4: 2 | S4: 10 | T4: 14 | U4: 3 | V4: 0 | W4: 0.162043 | X4: 0.11569841 | Y4: 0.22936356 | Z4: 0.019229719 | AA4: 0.060418107 | AB4: 0.25454545 | AC4: 0.213747 | AD4: =VLOOKUP(B:B,库存明细报表10.16!L:P,5,0) -> 3 | AE4: =VLOOKUP(B:B,库存明细报表10.16!L:Q,6,0) -> 3 | AF4: =VLOOKUP(B:B,库存明细报表10.16!L:T,9,0) -> 0 | AG4: =VLOOKUP(A:A,进销存报表10.16!A:J,10,0) -> 3 | AH4: =VLOOKUP(A:A,进销存报表10.16!A:K,11,0) -> 2 | AI4: 48.68 | AJ4: 40.86 | AK4: 0 | AL4: 9.3333333 | AM4: =AK4/AI4 -> 0 | AN4: =AL4/AJ4 -> 0.22842225
A5: OO2EWP11000 | B5: B0GWZL1L53 | C5: 6164EWP1104US | D5: FBA | E5: 维稳 | F5: 老品 | G5: 瘦狗 | H5: 瘦狗 | I5: 潜力 | J5: 25.99 | K5: 20.54 | L5: 20.32 | M5: 18.29 | N5: 22.35 | O5: 0 | P5: 0 | Q5: 0 | R5: 0 | S5: 5 | T5: 5 | U5: 1 | V5: 0 | W5: 0.11282211 | X5: -0.10904087 | Y5: 0.38983051 | Z5: 0.060071996 | AA5: 0.046719391 | AB5: 0.13513513 | AC5: 0.14244878 | AD5: =VLOOKUP(B:B,库存明细报表10.16!L:P,5,0) -> 15 | AE5: =VLOOKUP(B:B,库存明细报表10.16!L:Q,6,0) -> 15 | AF5: =VLOOKUP(B:B,库存明细报表10.16!L:T,9,0) -> 0 | AG5: =VLOOKUP(A:A,进销存报表10.16!A:J,10,0) -> 8 | AH5: =VLOOKUP(A:A,进销存报表10.16!A:K,11,0) -> 0 | AI5: 176.85 | AJ5: 101.32 | AK5: 0 | AL5: 3.6666667 | AM5: =AK5/AI5 -> 0 | AN5: =AL5/AJ5 -> 0.036188972
A6: OO2EWP05700 | B6: B0GWZGC7Q9 | C6: 5000EWP057FUS | D6: FBA | E6: 维稳 | F6: 老品 | G6: 瘦狗 | H6: 金牛 | I6: 潜力 | J6: 25.99 | K6: 21.94 | L6: 22.79 | M6: 20.51 | N6: 25.07 | O6: 0 | P6: 0 | Q6: 0 | R6: 13 | S6: 10 | T6: 0 | U6: 1 | V6: 0 | W6: 0.10810784 | X6: -0.7383248 | Y6: 0 | Z6: 1.3232558 | AA6: 0.003821135 | AB6: 0 | AC6: 0 | AD6: =VLOOKUP(B:B,库存明细报表10.16!L:P,5,0) -> 23 | AE6: =VLOOKUP(B:B,库存明细报表10.16!L:Q,6,0) -> 3 | AF6: =VLOOKUP(B:B,库存明细报表10.16!L:T,9,0) -> 0 | AG6: =VLOOKUP(A:A,进销存报表10.16!A:J,10,0) -> 3 | AH6: =VLOOKUP(A:A,进销存报表10.16!A:K,11,0) -> 21 | AI6: 122.21 | AJ6: 84.22 | AK6: 0 | AL6: 8.6666667 | AM6: =AK6/AI6 -> 0 | AN6: =AL6/AJ6 -> 0.10290509
A7: OO2EWP07200 | B7: B0GX5FC5K7 | C7: 3824EWP0720US | D7: FBA | E7: 维稳 | F7: 老品 | G7: 瘦狗 | H7: 瘦狗 | I7: 瘦狗 | J7: 22.99 | K7: 18.41 | L7: 19.41 | M7: 17.47 | N7: 21.35 | O7: 0 | P7: 0 | Q7: 0 | R7: 2 | S7: 2 | T7: 4 | U7: 6 | V7: 0 | W7: 0.17344889 | X7: 0.16822218 | Y7: 0 | Z7: 0.10305508 | AA7: 0.083855983 | AB7: 0.13793103 | AC7: 0.1869391 | AD7: =VLOOKUP(B:B,库存明细报表10.16!L:P,5,0) -> 17 | AE7: =VLOOKUP(B:B,库存明细报表10.16!L:Q,6,0) -> 14 | AF7: =VLOOKUP(B:B,库存明细报表10.16!L:T,9,0) -> 0 | AG7: =VLOOKUP(A:A,进销存报表10.16!A:J,10,0) -> 9 | AH7: =VLOOKUP(A:A,进销存报表10.16!A:K,11,0) -> 9 | AI7: 71.28 | AJ7: 47.77 | AK7: 0 | AL7: 2.6666667 | AM7: =AK7/AI7 -> 0 | AN7: =AL7/AJ7 -> 0.055823041
A8: OO2EWP11100 | B8: B0GWZBTZQ1 | C8: 1808EWP111ZUS | D8: FBA | E8: 维稳 | F8: 老品 | G8: 瘦狗 | H8: 瘦狗 | I8: 金牛 | J8: 31.99 | K8: 29.52 | L8: 29.52 | M8: 26.57 | N8: 32.47 | O8: 0 | P8: 0 | Q8: 0 | R8: 3 | S8: 6 | T8: 1 | U8: 2 | V8: 0 | W8: 0.029675854 | X8: 0 | Y8: 0 | Z8: #DIV/0! | AA8: #DIV/0! | AB8: 0.029411765 | AC8: 0.19945807 | AD8: =VLOOKUP(B:B,库存明细报表10.16!L:P,5,0) -> 19 | AE8: =VLOOKUP(B:B,库存明细报表10.16!L:Q,6,0) -> 19 | AF8: =VLOOKUP(B:B,库存明细报表10.16!L:T,9,0) -> 0 | AG8: =VLOOKUP(A:A,进销存报表10.16!A:J,10,0) -> 20 | AH8: =VLOOKUP(A:A,进销存报表10.16!A:K,11,0) -> 15 | AI8: 80.6 | AJ8: 40.8 | AK8: 0 | AL8: 3 | AM8: =AK8/AI8 -> 0 | AN8: =AL8/AJ8 -> 0.073529412
A9: OO2EWP11200 | B9: B0GWQXJ3LD | C9: 8557EWP1125US | D9: FBA | E9: 维稳 | F9: 老品 | G9: 瘦狗 | H9: 瘦狗 | I9: 金牛 | J9: 32.99 | K9: 21.69 | L9: 22.87 | M9: 20.58 | N9: 25.15 | O9: 0 | P9: 0 | Q9: 0 | R9: 0 | S9: 0 | T9: 1 | U9: 0 | V9: 0 | W9: 0.13382195 | X9: 0.19220113 | Y9: 0 | Z9: 0.12640194 | AA9: 0.08384568 | AB9: 0.035714286 | AC9: 0.12467398 | AD9: =VLOOKUP(B:B,库存明细报表10.16!L:P,5,0) -> 8 | AE9: =VLOOKUP(B:B,库存明细报表10.16!L:Q,6,0) -> 8 | AF9: =VLOOKUP(B:B,库存明细报表10.16!L:T,9,0) -> 2 | AG9: =VLOOKUP(A:A,进销存报表10.16!A:J,10,0) -> 18 | AH9: =VLOOKUP(A:A,进销存报表10.16!A:K,11,0) -> 3 | AI9: 27.29 | AJ9: 18.57 | AK9: 0 | AL9: 0.33333333 | AM9: =AK9/AI9 -> 0 | AN9: =AL9/AJ9 -> 0.017950099
A10: OO2EWP04400 | B10: B0GWZBPSDW | C10: 7785EWP044NUS | D10: FBA | E10: 维稳 | F10: 老品 | G10: 瘦狗 | H10: 金牛 | I10: 瘦狗 | J10: 45.99 | K10: 38.41 | L10: 42.24 | M10: 38.01 | N10: 46.46 | O10: 0 | P10: 0 | Q10: 0 | R10: 5 | S10: 2 | T10: 7 | U10: 1 | V10: 0 | W10: 0.072132173 | X10: 0.17543801 | Y10: 0 | Z10: 0.032056893 | AA10: 0.003821543 | AB10: 0.12962963 | AC10: 0.0554199 | AD10: =VLOOKUP(B:B,库存明细报表10.16!L:P,5,0) -> 19 | AE10: =VLOOKUP(B:B,库存明细报表10.16!L:Q,6,0) -> 19 | AF10: =VLOOKUP(B:B,库存明细报表10.16!L:T,9,0) -> 0 | AG10: =VLOOKUP(A:A,进销存报表10.16!A:J,10,0) -> 8 | AH10: =VLOOKUP(A:A,进销存报表10.16!A:K,11,0) -> 24 | AI10: 60.02 | AJ10: 45.02 | AK10: 0 | AL10: 5.3333333 | AM10: =AK10/AI10 -> 0 | AN10: =AL10/AJ10 -> 0.11846587
A11: OO2EWP09800 | B11: B0GWQPPJ13 | C11: 3544EWP0987US | D11: FBA | E11: 风险 | F11: 老品 | G11: 瘦狗 | H11: 潜力 | I11: 潜力 | J11: 27.99 | K11: 18.31 | L11: 20.33 | M11: 18.29 | N11: 22.36 | O11: 0 | P11: 1 | Q11: 0 | R11: 0 | S11: 4 | T11: 0 | U11: 1 | V11: 0 | W11: 0.30875024 | X11: 0 | Y11: 0 | Z11: #DIV/0! | AA11: #DIV/0! | AB11: 0 | AC11: 0 | AD11: =VLOOKUP(B:B,库存明细报表10.16!L:P,5,0) -> 27 | AE11: =VLOOKUP(B:B,库存明细报表10.16!L:Q,6,0) -> 26 | AF11: =VLOOKUP(B:B,库存明细报表10.16!L:T,9,0) -> 0 | AG11: =VLOOKUP(A:A,进销存报表10.16!A:J,10,0) -> 19 | AH11: =VLOOKUP(A:A,进销存报表10.16!A:K,11,0) -> 10 | AI11: 305.39 | AJ11: 160.5 | AK11: 0 | AL11: 1.3333333 | AM11: =AK11/AI11 -> 0 | AN11: =AL11/AJ11 -> 0.0083073728
A12: OO2EWP12200 | B12: B0GWQMTQY9 | C12: 1122EWP122BUS | D12: FBA | E12: 维稳 | F12: 老品 | G12: 瘦狗 | H12: 潜力 | I12: 瘦狗 | J12: 59.99 | K12: 47.22 | L12: 48.64 | M12: 43.77 | N12: 53.5 | O12: 0 | P12: 0 | Q12: 1 | R12: 0 | S12: 4 | T12: 6 | U12: 3 | V12: 0 | W12: 0.20762671 | X12: 0.20674177 | Y12: 0 | Z12: 0.0265322 | AA12: 0.058830725 | AB12: 0.12765957 | AC12: 0.05865822 | AD12: =VLOOKUP(B:B,库存明细报表10.16!L:P,5,0) -> 4 | AE12: =VLOOKUP(B:B,库存明细报表10.16!L:Q,6,0) -> 2 | AF12: =VLOOKUP(B:B,库存明细报表10.16!L:T,9,0) -> 2 | AG12: =VLOOKUP(A:A,进销存报表10.16!A:J,10,0) -> 4 | AH12: =VLOOKUP(A:A,进销存报表10.16!A:K,11,0) -> 26 | AI12: 112.19 | AJ12: 100.12 | AK12: 0 | AL12: 3.6666667 | AM12: =AK12/AI12 -> 0 | AN12: =AL12/AJ12 -> 0.036622719
A13: OO2EWP05600 | B13: B0GWZHYY3T | C13: 5706EWP0564US | D13: FBA | E13: 风险 | F13: 老品 | G13: 瘦狗 | H13: 瘦狗 | I13: 瘦狗 | J13: 35.99 | K13: 31.15 | L13: 38.89 | M13: 35 | N13: 42.78 | O13: 0 | P13: 0 | Q13: 0 | R13: 0 | S13: 0 | T13: 1 | U13: 3 | V13: 0 | W13: 0.017581344 | X13: 0.10736848 | Y13: 0 | Z13: 0.084637086 | AA13: 0.083842075 | AB13: 0.034482759 | AC13: 0.14252045 | AD13: =VLOOKUP(B:B,库存明细报表10.16!L:P,5,0) -> 28 | AE13: =VLOOKUP(B:B,库存明细报表10.16!L:Q,6,0) -> 28 | AF13: =VLOOKUP(B:B,库存明细报表10.16!L:T,9,0) -> 0 | AG13: =VLOOKUP(A:A,进销存报表10.16!A:J,10,0) -> 1 | AH13: =VLOOKUP(A:A,进销存报表10.16!A:K,11,0) -> 7 | AI13: 85.95 | AJ13: 56.52 | AK13: 0 | AL13: 0.33333333 | AM13: =AK13/AI13 -> 0 | AN13: =AL13/AJ13 -> 0.0058976174
A14: OO2EWP12700 | B14: B0GWQXP1D2 | C14: 1432EWP127JUS | D14: FBA | E14: 维稳 | F14: 老品 | G14: 瘦狗 | H14: 瘦狗 | I14: 瘦狗 | J14: 45.99 | K14: 39.85 | L14: 43.92 | M14: 39.53 | N14: 48.32 | O14: 0 | P14: 0 | Q14: 0 | R14: 1 | S14: 1 | T14: 13 | U14: 1 | V14: 0 | W14: 0.0689396 | X14: 0.056724794 | Y14: 0.23076923 | Z14: 0.017662703 | AA14: 0.025364691 | AB14: 0.15853659 | AC14: 0.207875 | AD14: =VLOOKUP(B:B,库存明细报表10.16!L:P,5,0) -> 1 | AE14: =VLOOKUP(B:B,库存明细报表10.16!L:Q,6,0) -> 0 | AF14: =VLOOKUP(B:B,库存明细报表10.16!L:T,9,0) -> 0 | AG14: =VLOOKUP(A:A,进销存报表10.16!A:J,10,0) -> 16 | AH14: =VLOOKUP(A:A,进销存报表10.16!A:K,11,0) -> 14 | AI14: 166.85 | AJ14: 144.26 | AK14: 0 | AL14: 5 | AM14: =AK14/AI14 -> 0 | AN14: =AL14/AJ14 -> 0.034659642
A15: OO2EWP10300 | B15: B0GX52JVGN | C15: 4061EWP103QUS | D15: FBA | E15: 风险 | F15: 老品 | G15: 瘦狗 | H15: 明星 | I15: 明星 | J15: 26.99 | K15: 19.3 | L15: 22.23 | M15: 20.01 | N15: 24.46 | O15: 0 | P15: 0 | Q15: 0 | R15: 0 | S15: 0 | T15: 0 | U15: 0 | V15: 0 | W15: 0.3029256 | X15: 0.38975378 | Y15: 0 | Z15: 0.14338644 | AA15: 0.083851225 | AB15: 0 | AC15: 0 | AD15: =VLOOKUP(B:B,库存明细报表10.16!L:P,5,0) -> 10 | AE15: =VLOOKUP(B:B,库存明细报表10.16!L:Q,6,0) -> 10 | AF15: =VLOOKUP(B:B,库存明细报表10.16!L:T,9,0) -> 3 | AG15: =VLOOKUP(A:A,进销存报表10.16!A:J,10,0) -> 15 | AH15: =VLOOKUP(A:A,进销存报表10.16!A:K,11,0) -> 0 | AI15: 3.41 | AJ15: 2.74 | AK15: 0 | AL15: 0.33333333 | AM15: =AK15/AI15 -> 0 | AN15: =AL15/AJ15 -> 0.1216545
A16: OO2EWP05100 | B16: B0GWZR3D55 | C16: 8759EWP051TUS | D16: FBA | E16: 维稳 | F16: 老品 | G16: 瘦狗 | H16: 潜力 | I16: 瘦狗 | J16: 37.99 | K16: 31.41 | L16: 33.23 | M16: 29.91 | N16: 36.55 | O16: 0 | P16: 0 | Q16: 1 | R16: 2 | S16: 3 | T16: 4 | U16: 1 | V16: 0 | W16: 0.22408861 | X16: 0.22237719 | Y16: 0.25016462 | Z16: 0.044712235 | AA16: 0.063811002 | AB16: 0.11764706 | AC16: 0.076722407 | AD16: =VLOOKUP(B:B,库存明细报表10.16!L:P,5,0) -> 5 | AE16: =VLOOKUP(B:B,库存明细报表10.16!L:Q,6,0) -> 1 | AF16: =VLOOKUP(B:B,库存明细报表10.16!L:T,9,0) -> 0 | AG16: =VLOOKUP(A:A,进销存报表10.16!A:J,10,0) -> 5 | AH16: =VLOOKUP(A:A,进销存报表10.16!A:K,11,0) -> 0 | AI16: 53.38 | AJ16: 39.8 | AK16: 0 | AL16: 3.6666667 | AM16: =AK16/AI16 -> 0 | AN16: =AL16/AJ16 -> 0.092127303
A17: OO2EWP04500 | B17: B0GYRP5X4D | C17: 4601EWP045HUS | D17: FBA | E17: 风险 | F17: 老品 | G17: 瘦狗 | H17: 潜力 | I17: 潜力 | J17: 31.99 | K17: 23.56 | L17: 31.41 | M17: 28.27 | N17: 34.56 | O17: 0 | P17: 0 | Q17: 0 | R17: 0 | S17: 2 | T17: 2 | U17: 1 | V17: 0 | W17: 0.21463789 | X17: 0.17609004 | Y17: 0 | Z17: 0.051161821 | AA17: 0.083846551 | AB17: 0.058823529 | AC17: 0.16632504 | AD17: =VLOOKUP(B:B,库存明细报表10.16!L:P,5,0) -> 13 | AE17: =VLOOKUP(B:B,库存明细报表10.16!L:Q,6,0) -> 13 | AF17: =VLOOKUP(B:B,库存明细报表10.16!L:T,9,0) -> 0 | AG17: =VLOOKUP(A:A,进销存报表10.16!A:J,10,0) -> 46 | AH17: =VLOOKUP(A:A,进销存报表10.16!A:K,11,0) -> 0 | AI17: 78.55 | AJ17: 44.71 | AK17: 0 | AL17: 1.6666667 | AM17: =AK17/AI17 -> 0 | AN17: =AL17/AJ17 -> 0.037277268
A18: OO2EWP07700 | B18: B0GYS61TK1 | C18: 2891EWP077AUS | D18: FBA | E18: 维稳 | F18: 老品 | G18: 瘦狗 | H18: 瘦狗 | I18: 潜力 | J18: 25.99 | K18: 20.78 | L18: 24.67 | M18: 22.2 | N18: 27.13 | O18: 0 | P18: 0 | Q18: 0 | R18: 0 | S18: 0 | T18: 2 | U18: 1 | V18: 0 | W18: 0.12263473 | X18: 0.1645322 | Y18: 0 | Z18: 0.046432616 | AA18: 0.083851748 | AB18: 0.14285714 | AC18: 0 | AD18: =VLOOKUP(B:B,库存明细报表10.16!L:P,5,0) -> 12 | AE18: =VLOOKUP(B:B,库存明细报表10.16!L:Q,6,0) -> 12 | AF18: =VLOOKUP(B:B,库存明细报表10.16!L:T,9,0) -> 0 | AG18: =VLOOKUP(A:A,进销存报表10.16!A:J,10,0) -> 10 | AH18: =VLOOKUP(A:A,进销存报表10.16!A:K,11,0) -> 51 | AI18: 273.16 | AJ18: 229.46 | AK18: 0 | AL18: 0.66666667 | AM18: =AK18/AI18 -> 0 | AN18: =AL18/AJ18 -> 0.002905372
A19: OO2EWP07800 | B19: B0GYRNV2Q2 | C19: 8531EWP078GUS | D19: FBA | E19: 维稳 | F19: 老品 | G19: 瘦狗 | H19: 潜力 | I19: 瘦狗 | J19: 39.99 | K19: 32.08 | L19: 47.1 | M19: 42.39 | N19: 51.81 | O19: 0 | P19: 0 | Q19: 0 | R19: 1 | S19: 0 | T19: 4 | U19: 2 | V19: 0 | W19: 0.22955863 | X19: 0.29320124 | Y19: 0 | Z19: 0.024765004 | AA19: 0.042385051 | AB19: 0.18181818 | AC19: 0.19958913 | AD19: =VLOOKUP(B:B,库存明细报表10.16!L:P,5,0) -> 5 | AE19: =VLOOKUP(B:B,库存明细报表10.16!L:Q,6,0) -> 5 | AF19: =VLOOKUP(B:B,库存明细报表10.16!L:T,9,0) -> 0 | AG19: =VLOOKUP(A:A,进销存报表10.16!A:J,10,0) -> 0 | AH19: =VLOOKUP(A:A,进销存报表10.16!A:K,11,0) -> 50 | AI19: 146.93 | AJ19: 65.38 | AK19: 0 | AL19: 1.6666667 | AM19: =AK19/AI19 -> 0 | AN19: =AL19/AJ19 -> 0.025491996
A20: OO2EWP07300 | B20: B0FZGM1YGD | C20: 7835EWP073GUS | D20: FBA | E20: 维稳 | F20: 老品 | G20: 瘦狗 | H20: 金牛 | I20: 瘦狗 | J20: 85.99 | K20: 63.59 | L20: 71.24 | M20: 64.11 | N20: 78.36 | O20: 0 | P20: 0 | Q20: 0 | R20: 5 | S20: 3 | T20: 1 | U20: 0 | V20: 0 | W20: 0.16375031 | X20: 0 | Y20: 0 | Z20: #DIV/0! | AA20: #DIV/0! | AB20: 0.055555556 | AC20: 0 | AD20: =VLOOKUP(B:B,库存明细报表10.16!L:P,5,0) -> 6 | AE20: =VLOOKUP(B:B,库存明细报表10.16!L:Q,6,0) -> 6 | AF20: =VLOOKUP(B:B,库存明细报表10.16!L:T,9,0) -> 0 | AG20: =VLOOKUP(A:A,进销存报表10.16!A:J,10,0) -> 4 | AH20: =VLOOKUP(A:A,进销存报表10.16!A:K,11,0) -> 8 | AI20: 33.15 | AJ20: 25.37 | AK20: 0 | AL20: 2.6666667 | AM20: =AK20/AI20 -> 0 | AN20: =AL20/AJ20 -> 0.10511102
A21: OO2EWP07600 | B21: B0GWZHV9LG | C21: 8571EWP076LUS | D21: FBA | E21: 风险 | F21: 老品 | G21: 瘦狗 | H21: 潜力 | I21: 潜力 | J21: 33.99 | K21: 25.01 | L21: 31.36 | M21: 28.22 | N21: 34.49 | O21: 0 | P21: 1 | Q21: 1 | R21: 4 | S21: 6 | T21: 6 | U21: 6 | V21: -0.22624968 | W21: 0.22097021 | X21: 0.20495294 | Y21: 0.12658274 | Z21: 0.019137544 | AA21: 0.076175209 | AB21: 0.12244898 | AC21: 0.24944807 | AD21: =VLOOKUP(B:B,库存明细报表10.16!L:P,5,0) -> 26 | AE21: =VLOOKUP(B:B,库存明细报表10.16!L:Q,6,0) -> 26 | AF21: =VLOOKUP(B:B,库存明细报表10.16!L:T,9,0) -> 0 | AG21: =VLOOKUP(A:A,进销存报表10.16!A:J,10,0) -> 11 | AH21: =VLOOKUP(A:A,进销存报表10.16!A:K,11,0) -> 0 | AI21: 327.34 | AJ21: 194.02 | AK21: 0.33 | AL21: 6 | AM21: =AK21/AI21 -> 0.0010081261 | AN21: =AL21/AJ21 -> 0.030924647
A22: OO2EWP03900 | B22: B0GWQRKH9G | C22: 9693EWP0397US | D22: FBA | E22: 维稳 | F22: 老品 | G22: 瘦狗 | H22: 瘦狗 | I22: 瘦狗 | J22: 27.99 | K22: 24.31 | L22: 23.74 | M22: 21.37 | N22: 26.11 | O22: 0 | P22: 0 | Q22: 2 | R22: 6 | S22: 3 | T22: 0 | U22: 2 | V22: 0.081142765 | W22: 0.096450859 | X22: 0 | Y22: 0 | Z22: #DIV/0! | AA22: #DIV/0! | AB22: 0 | AC22: 0 | AD22: =VLOOKUP(B:B,库存明细报表10.16!L:P,5,0) -> 7 | AE22: =VLOOKUP(B:B,库存明细报表10.16!L:Q,6,0) -> 7 | AF22: =VLOOKUP(B:B,库存明细报表10.16!L:T,9,0) -> 0 | AG22: =VLOOKUP(A:A,进销存报表10.16!A:J,10,0) -> 29 | AH22: =VLOOKUP(A:A,进销存报表10.16!A:K,11,0) -> 27 | AI22: 347.13 | AJ22: 242.79 | AK22: 0.67 | AL22: 3.3333333 | AM22: =AK22/AI22 -> 0.0019301126 | AN22: =AL22/AJ22 -> 0.013729286
A23: OO2EWP02600 | B23: B0GWZ8Q8L2 | C23: 4673EWP026JUS | D23: FBA | E23: 维稳 | F23: 老品 | G23: 瘦狗 | H23: 潜力 | I23: 瘦狗 | J23: 22.99 | K23: 16.52 | L23: 18.84 | M23: 16.96 | N23: 20.73 | O23: 0 | P23: 0 | Q23: 2 | R23: 9 | S23: 5 | T23: 7 | U23: 4 | V23: 0.13278429 | W23: 0.20965005 | X23: 0.19286386 | Y23: 0 | Z23: 0.075979472 | AA23: 0.072353274 | AB23: 0.11111111 | AC23: 0 | AD23: =VLOOKUP(B:B,库存明细报表10.16!L:P,5,0) -> 27 | AE23: =VLOOKUP(B:B,库存明细报表10.16!L:Q,6,0) -> 26 | AF23: =VLOOKUP(B:B,库存明细报表10.16!L:T,9,0) -> 0 | AG23: =VLOOKUP(A:A,进销存报表10.16!A:J,10,0) -> 3 | AH23: =VLOOKUP(A:A,进销存报表10.16!A:K,11,0) -> 28 | AI23: 318 | AJ23: 232.58 | AK23: 0.67 | AL23: 7 | AM23: =AK23/AI23 -> 0.0021069182 | AN23: =AL23/AJ23 -> 0.030097171
A24: OO2EWP03100 | B24: B0GWZNCP7S | C24: 6070EWP0315US | D24: FBA | E24: 维稳 | F24: 老品 | G24: 潜力 | H24: 瘦狗 | I24: 潜力 | J24: 38.99 | K24: 32.05 | L24: 37.99 | M24: 34.19 | N24: 41.79 | O24: 0 | P24: 0 | Q24: 1 | R24: 7 | S24: 2 | T24: 0 | U24: 1 | V24: 0.23143232 | W24: 0.16010831 | X24: 0 | Y24: 0 | Z24: #DIV/0! | AA24: #DIV/0! | AB24: 0 | AC24: 0 | AD24: =VLOOKUP(B:B,库存明细报表10.16!L:P,5,0) -> 9 | AE24: =VLOOKUP(B:B,库存明细报表10.16!L:Q,6,0) -> 0 | AF24: =VLOOKUP(B:B,库存明细报表10.16!L:T,9,0) -> 0 | AG24: =VLOOKUP(A:A,进销存报表10.16!A:J,10,0) -> 8 | AH24: =VLOOKUP(A:A,进销存报表10.16!A:K,11,0) -> 26 | AI24: 155.92 | AJ24: 123.99 | AK24: 0.33 | AL24: 3.3333333 | AM24: =AK24/AI24 -> 0.00211647 | AN24: =AL24/AJ24 -> 0.026883888
A25: OO2EWP08900 | B25: B0GWQNW9QC | C25: 3328EWP089HUS | D25: FBA | E25: 维稳 | F25: 老品 | G25: 潜力 | H25: 瘦狗 | I25: 潜力 | J25: 24.99 | K25: 19.05 | L25: 23.99 | M25: 21.59 | N25: 26.39 | O25: 0 | P25: 0 | Q25: 1 | R25: 1 | S25: 1 | T25: 2 | U25: 1 | V25: 0.30960216 | W25: 0.088390617 | X25: 0.062125706 | Y25: 0 | Z25: 0.084433774 | AA25: 0.083853506 | AB25: 0.095238095 | AC25: 0.036980607 | AD25: =VLOOKUP(B:B,库存明细报表10.16!L:P,5,0) -> 11 | AE25: =VLOOKUP(B:B,库存明细报表10.16!L:Q,6,0) -> 10 | AF25: =VLOOKUP(B:B,库存明细报表10.16!L:T,9,0) -> 2 | AG25: =VLOOKUP(A:A,进销存报表10.16!A:J,10,0) -> 21 | AH25: =VLOOKUP(A:A,进销存报表10.16!A:K,11,0) -> 1 | AI25: 153.58 | AJ25: 115.22 | AK25: 0.33 | AL25: 1.3333333 | AM25: =AK25/AI25 -> 0.0021487173 | AN25: =AL25/AJ25 -> 0.011572065
A26: ZC2CLK04900 | B26: B0GWQVBRBB | C26: 6936CLK0491US | D26: FBA | E26: 维稳 | F26: 老品 | G26: 潜力 | H26: 潜力 | I26: 潜力 | J26: 38.99 | K26: 22.2 | L26: 38.95 | M26: 35.05 | N26: 42.84 | O26: 0 | P26: 0 | Q26: 1 | R26: 1 | S26: 1 | T26: 4 | U26: 0 | V26: 0.38353171 | W26: 0.30951289 | X26: 0.31383031 | Y26: 0 | Z26: 0.065070493 | AA26: 0.083824903 | AB26: 0.11764706 | AC26: 0.10696505 | AD26: =VLOOKUP(B:B,库存明细报表10.16!L:P,5,0) -> 15 | AE26: =VLOOKUP(B:B,库存明细报表10.16!L:Q,6,0) -> 14 | AF26: =VLOOKUP(B:B,库存明细报表10.16!L:T,9,0) -> 0 | AG26: =VLOOKUP(A:A,进销存报表10.16!A:J,10,0) -> 19 | AH26: =VLOOKUP(A:A,进销存报表10.16!A:K,11,0) -> 12 | AI26: 131.47 | AJ26: 90.4 | AK26: 0.33 | AL26: 1.6666667 | AM26: =AK26/AI26 -> 0.0025100783 | AN26: =AL26/AJ26 -> 0.018436578
A27: OO2EWP08000 | B27: B0G3LJ3LGP | C27: 3150EWP080GUS | D27: FBA | E27: 维稳 | F27: 老品 | G27: 瘦狗 | H27: 瘦狗 | I27: 瘦狗 | J27: 37.99 | K27: 29.95 | L27: 35.19 | M27: 31.67 | N27: 38.71 | O27: 0 | P27: 1 | Q27: 4 | R27: 6 | S27: 5 | T27: 4 | U27: 1 | V27: 0.18804262 | W27: 0.176674 | X27: 0.47464876 | Y27: 0 | Z27: 0.047349961 | AA27: 0.083842339 | AB27: 0.070175439 | AC27: 0.19951349 | AD27: =VLOOKUP(B:B,库存明细报表10.16!L:P,5,0) -> 29 | AE27: =VLOOKUP(B:B,库存明细报表10.16!L:Q,6,0) -> 29 | AF27: =VLOOKUP(B:B,库存明细报表10.16!L:T,9,0) -> 0 | AG27: =VLOOKUP(A:A,进销存报表10.16!A:J,10,0) -> 0 | AH27: =VLOOKUP(A:A,进销存报表10.16!A:K,11,0) -> 83 | AI27: 634.05 | AJ27: 472.58 | AK27: 1.67 | AL27: 5 | AM27: =AK27/AI27 -> 0.0026338617 | AN27: =AL27/AJ27 -> 0.010580219
A28: OO2EWP08600 | B28: B0GWQTZDGZ | C28: 4633EWP0866US | D28: FBA | E28: 维稳 | F28: 老品 | G28: 潜力 | H28: 瘦狗 | I28: 瘦狗 | J28: 53.99 | K28: 45.43 | L28: 46.54 | M28: 41.88 | N28: 51.19 | O28: 0 | P28: 1 | Q28: 0 | R28: 6 | S28: 6 | T28: 8 | U28: 6 | V28: 0.27483858 | W28: 0.19843972 | X28: 0.18035891 | Y28: 0.25225266 | Z28: 0.023269959 | AA28: 0.051037269 | AB28: 0.15384615 | AC28: 0.15349244 | AD28: =VLOOKUP(B:B,库存明细报表10.16!L:P,5,0) -> 17 | AE28: =VLOOKUP(B:B,库存明细报表10.16!L:Q,6,0) -> 6 | AF28: =VLOOKUP(B:B,库存明细报表10.16!L:T,9,0) -> 2 | AG28: =VLOOKUP(A:A,进销存报表10.16!A:J,10,0) -> 21 | AH28: =VLOOKUP(A:A,进销存报表10.16!A:K,11,0) -> 10 | AI28: 107.6 | AJ28: 85.99 | AK28: 0.33 | AL28: 6.6666667 | AM28: =AK28/AI28 -> 0.0030669145 | AN28: =AL28/AJ28 -> 0.077528395
A29: OO2EWP07900 | B29: B0DSW8XVPB | C29: 7900EWP0795US | D29: FBA | E29: 维稳 | F29: 老品 | G29: 瘦狗 | H29: 潜力 | I29: 潜力 | J29: 59.99 | K29: 40.31 | L29: 47.49 | M29: 42.74 | N29: 52.24 | O29: 0 | P29: 0 | Q29: 3 | R29: 2 | S29: 5 | T29: 9 | U29: 6 | V29: 0.19749434 | W29: 0.28267932 | X29: 0.29774235 | Y29: 0 | Z29: 0.001364657 | AA29: 0.041133697 | AB29: 0.25 | AC29: 0 | AD29: =VLOOKUP(B:B,库存明细报表10.16!L:P,5,0) -> 32 | AE29: =VLOOKUP(B:B,库存明细报表10.16!L:Q,6,0) -> 31 | AF29: =VLOOKUP(B:B,库存明细报表10.16!L:T,9,0) -> 0 | AG29: =VLOOKUP(A:A,进销存报表10.16!A:J,10,0) -> 42 | AH29: =VLOOKUP(A:A,进销存报表10.16!A:K,11,0) -> 2 | AI29: 396.21 | AJ29: 333.63 | AK29: 1.33 | AL29: 5.3333333 | AM29: =AK29/AI29 -> 0.0033568057 | AN29: =AL29/AJ29 -> 0.015985773
A30: OO2EWP02100 | B30: B0GWQY9RW4 | C30: 9087EWP021RUS | D30: FBA | E30: 风险 | F30: 老品 | G30: 潜力 | H30: 瘦狗 | I30: 潜力 | J30: 25.99 | K30: 22.59 | L30: 18.58 | M30: 16.72 | N30: 20.44 | O30: 0 | P30: 0 | Q30: 2 | R30: 1 | S30: 10 | T30: 2 | U30: 0 | V30: 0.28375521 | W30: 0.049795808 | X30: 0.24754104 | Y30: 0 | Z30: 0.04546355 | AA30: 0.024383773 | AB30: 0.05 | AC30: 0.1246411 | AD30: =VLOOKUP(B:B,库存明细报表10.16!L:P,5,0) -> 5 | AE30: =VLOOKUP(B:B,库存明细报表10.16!L:Q,6,0) -> 1 | AF30: =VLOOKUP(B:B,库存明细报表10.16!L:T,9,0) -> 0 | AG30: =VLOOKUP(A:A,进销存报表10.16!A:J,10,0) -> 18 | AH30: =VLOOKUP(A:A,进销存报表10.16!A:K,11,0) -> 8 | AI30: 189.31 | AJ30: 164.27 | AK30: 0.67 | AL30: 4.6666667 | AM30: =AK30/AI30 -> 0.0035391686 | AN30: =AL30/AJ30 -> 0.028408514
A31: OO2EWP10700 | B31: B0GWZHZJXQ | C31: 4417EWP107SUS | D31: FBA | E31: 维稳 | F31: 老品 | G31: 瘦狗 | H31: 瘦狗 | I31: 潜力 | J31: 27.99 | K31: 19.85 | L31: 19.27 | M31: 17.34 | N31: 21.2 | O31: 0 | P31: 0 | Q31: 1 | R31: 4 | S31: 4 | T31: 9 | U31: 5 | V31: 0.01795781 | W31: 0.19576777 | X31: 0.26137279 | Y31: 0 | Z31: 0.053352388 | AA31: 0.074958072 | AB31: 0.13846154 | AC31: 0.16629319 | AD31: =VLOOKUP(B:B,库存明细报表10.16!L:P,5,0) -> 8 | AE31: =VLOOKUP(B:B,库存明细报表10.16!L:Q,6,0) -> 8 | AF31: =VLOOKUP(B:B,库存明细报表10.16!L:T,9,0) -> 0 | AG31: =VLOOKUP(A:A,进销存报表10.16!A:J,10,0) -> 5 | AH31: =VLOOKUP(A:A,进销存报表10.16!A:K,11,0) -> 16 | AI31: 91.06 | AJ31: 61.56 | AK31: 0.33 | AL31: 6 | AM31: =AK31/AI31 -> 0.0036239842 | AN31: =AL31/AJ31 -> 0.097465887
A32: OO2EWP05000 | B32: B0GWZKWRT4 | C32: 6571EWP050XUS | D32: FBA | E32: 维稳 | F32: 老品 | G32: 潜力 | H32: 瘦狗 | I32: 潜力 | J32: 21.99 | K32: 20.85 | L32: 17.57 | M32: 15.81 | N32: 19.33 | O32: 0 | P32: 0 | Q32: 1 | R32: 0 | S32: 5 | T32: 8 | U32: 9 | V32: 0.34725141 | W32: 0.088299283 | X32: 0.004619175 | Y32: 0.12622019 | Z32: 0.071438978 | AA32: 0.073755017 | AB32: 0.1038961 | AC32: 0.083134443 | AD32: =VLOOKUP(B:B,库存明细报表10.16!L:P,5,0) -> 4 | AE32: =VLOOKUP(B:B,库存明细报表10.16!L:Q,6,0) -> 4 | AF32: =VLOOKUP(B:B,库存明细报表10.16!L:T,9,0) -> 0 | AG32: =VLOOKUP(A:A,进销存报表10.16!A:J,10,0) -> 0 | AH32: =VLOOKUP(A:A,进销存报表10.16!A:K,11,0) -> 0 | AI32: 89.74 | AJ32: 62.2 | AK32: 0.33 | AL32: 4.6666667 | AM32: =AK32/AI32 -> 0.0036772899 | AN32: =AL32/AJ32 -> 0.075026795
A33: OO2EWP03000 | B33: B0GWZPSHM2 | C33: 8131EWP0300US | D33: FBA | E33: 风险 | F33: 老品 | G33: 瘦狗 | H33: 瘦狗 | I33: 瘦狗 | J33: 69.99 | K33: 66.66 | L33: 60.79 | M33: 54.71 | N33: 66.87 | O33: 0 | P33: 5 | Q33: 5 | R33: 1 | S33: 1 | T33: 2 | U33: 0 | V33: -0.050532872 | W33: 0.090402945 | X33: 0.085295012 | Y33: 0 | Z33: 0.05971304 | AA33: 0.088784262 | AB33: 0.068965517 | AC33: 0.049893831 | AD33: =VLOOKUP(B:B,库存明细报表10.16!L:P,5,0) -> 19 | AE33: =VLOOKUP(B:B,库存明细报表10.16!L:Q,6,0) -> 18 | AF33: =VLOOKUP(B:B,库存明细报表10.16!L:T,9,0) -> 0 | AG33: =VLOOKUP(A:A,进销存报表10.16!A:J,10,0) -> 37 | AH33: =VLOOKUP(A:A,进销存报表10.16!A:K,11,0) -> 12 | AI33: 753.52 | AJ33: 522.41 | AK33: 3 | AL33: 1.6666667 | AM33: =AK33/AI33 -> 0.0039813144 | AN33: =AL33/AJ33 -> 0.0031903422
A34: OO2EWP10800 | B34: B0GX5DMQLL | C34: 4030EWP108VUS | D34: FBA | E34: 维稳 | F34: 老品 | G34: 瘦狗 | H34: 瘦狗 | I34: 潜力 | J34: 25.99 | K34: 18.67 | L34: 22.79 | M34: 20.51 | N34: 25.06 | O34: 0 | P34: 0 | Q34: 1 | R34: 4 | S34: 4 | T34: 3 | U34: 0 | V34: 0.18498106 | W34: 0.11711769 | X34: -0.013370955 | Y34: 0.31587263 | Z34: 0.090544482 | AA34: 0.054380623 | AB34: 0.125 | AC34: 0.24922416 | AD34: =VLOOKUP(B:B,库存明细报表10.16!L:P,5,0) -> 15 | AE34: =VLOOKUP(B:B,库存明细报表10.16!L:Q,6,0) -> 15 | AF34: =VLOOKUP(B:B,库存明细报表10.16!L:T,9,0) -> 0 | AG34: =VLOOKUP(A:A,进销存报表10.16!A:J,10,0) -> 15 | AH34: =VLOOKUP(A:A,进销存报表10.16!A:K,11,0) -> 22 | AI34: 79.27 | AJ34: 46.94 | AK34: 0.33 | AL34: 4.3333333 | AM34: =AK34/AI34 -> 0.0041629873 | AN34: =AL34/AJ34 -> 0.092316432
A35: OO2EWP11300 | B35: B0GWQXQT6R | C35: 7505EWP1139US | D35: FBA | E35: 维稳 | F35: 老品 | G35: 瘦狗 | H35: 金牛 | I35: 瘦狗 | J35: 45.99 | K35: 36.44 | L35: 34.49 | M35: 31.04 | N35: 37.94 | O35: 0 | P35: 0 | Q35: 2 | R35: 7 | S35: 14 | T35: 2 | U35: 3 | V35: 0.18125014 | W35: 0.077713561 | X35: 0.078995459 | Y35: 0.44224909 | Z35: 0.003637079 | AA35: -0.040413238 | AB35: 0.5 | AC35: 0.99820025 | AD35: =VLOOKUP(B:B,库存明细报表10.16!L:P,5,0) -> 2 | AE35: =VLOOKUP(B:B,库存明细报表10.16!L:Q,6,0) -> 2 | AF35: =VLOOKUP(B:B,库存明细报表10.16!L:T,9,0) -> 11 | AG35: =VLOOKUP(A:A,进销存报表10.16!A:J,10,0) -> 0 | AH35: =VLOOKUP(A:A,进销存报表10.16!A:K,11,0) -> 8 | AI35: 149.96 | AJ35: 82.85 | AK35: 0.67 | AL35: 9.3333333 | AM35: =AK35/AI35 -> 0.0044678581 | AN35: =AL35/AJ35 -> 0.11265339
A36: OO2EWP11900 | B36: B0GWZH2JVV | C36: 1189EWP119BUS | D36: FBA | E36: 维稳 | F36: 老品 | G36: 潜力 | H36: 金牛 | I36: 瘦狗 | J36: 66.99 | K36: 54.13 | L36: 54.78 | M36: 49.3 | N36: 60.25 | O36: 0 | P36: 0 | Q36: 1 | R36: 2 | S36: 4 | T36: 6 | U36: 1 | V36: 0.2347088 | W36: 0.17234422 | X36: 0.092458435 | Y36: 0 | Z36: 0.007135393 | AA36: 0.093834993 | AB36: 0.24 | AC36: 0 | AD36: =VLOOKUP(B:B,库存明细报表10.16!L:P,5,0) -> 6 | AE36: =VLOOKUP(B:B,库存明细报表10.16!L:Q,6,0) -> 5 | AF36: =VLOOKUP(B:B,库存明细报表10.16!L:T,9,0) -> 0 | AG36: =VLOOKUP(A:A,进销存报表10.16!A:J,10,0) -> 1 | AH36: =VLOOKUP(A:A,进销存报表10.16!A:K,11,0) -> 23 | AI36: 55.14 | AJ36: 39.25 | AK36: 0.33 | AL36: 4 | AM36: =AK36/AI36 -> 0.0059847661 | AN36: =AL36/AJ36 -> 0.10191083
... A40: OO2EWP12000 | B40: B0GWQSPYL6 | C40: 8948EWP1204US | D40: FBA | E40: 维稳 | F40: 老品 | G40: 潜力 | H40: 瘦狗 | I40: 明星 | J40: 29.99 | K40: 22.42 | L40: 28.36 | M40: 25.52 | N40: 31.19 | O40: 0 | P40: 1 | Q40: 0 | R40: 3 | S40: 2 | T40: 1 | U40: 1 | V40: 0.25492005 | W40: 0.12104269 | X40: -0.059893165 | Y40: 0 | Z40: 0.2354118 | AA40: 0.083848185 | AB40: 0.034482759 | AC40: 0 | AD40: =VLOOKUP(B:B,库存明细报表10.16!L:P,5,0) -> 21 | AE40: =VLOOKUP(B:B,库存明细报表10.16!L:Q,6,0) -> 14 | AF40: =VLOOKUP(B:B,库存明细报表10.16!L:T,9,0) -> 17 | AG40: =VLOOKUP(A:A,进销存报表10.16!A:J,10,0) -> 15 | AH40: =VLOOKUP(A:A,进销存报表10.16!A:K,11,0) -> 13 | AI40: 42.26 | AJ40: 27.83 | AK40: 0.33 | AL40: 2 | AM40: =AK40/AI40 -> 0.0078088027 | AN40: =AL40/AJ40 -> 0.071864894
A41: OO2EWP09700 | B41: B0FLK4C864 | C41: 9920EWP097BUS | D41: FBA | E41: 维稳 | F41: 老品 | G41: 瘦狗 | H41: 瘦狗 | I41: 潜力 | J41: 25.99 | K41: 16.51 | L41: 21.96 | M41: 19.76 | N41: 24.16 | O41: 2 | P41: 3 | Q41: 2 | R41: 2 | S41: 2 | T41: 1 | U41: 2 | V41: 0.19787915 | W41: 0.18670803 | X41: 0 | Y41: 0 | Z41: #DIV/0! | AA41: #DIV/0! | AB41: 0.05 | AC41: 0 | AD41: =VLOOKUP(B:B,库存明细报表10.16!L:P,5,0) -> 0 | AE41: =VLOOKUP(B:B,库存明细报表10.16!L:Q,6,0) -> 0 | AF41: =VLOOKUP(B:B,库存明细报表10.16!L:T,9,0) -> 15 | AG41: =VLOOKUP(A:A,进销存报表10.16!A:J,10,0) -> 34 | AH41: =VLOOKUP(A:A,进销存报表10.16!A:K,11,0) -> 0 | AI41: 238.06 | AJ41: 209.54 | AK41: 2 | AL41: 1.6666667 | AM41: =AK41/AI41 -> 0.0084012434 | AN41: =AL41/AJ41 -> 0.0079539308
A42: OO2EWP05900 | B42: B0GWQLN3LT | C42: 2193EWP059HUS | D42: FBA | E42: 维稳 | F42: 老品 | G42: 潜力 | H42: 明星 | I42: 潜力 | J42: 42.99 | K42: 31.01 | L42: 34.28 | M42: 30.86 | N42: 37.71 | O42: 0 | P42: 1 | Q42: 1 | R42: 7 | S42: 15 | T42: 6 | U42: 1 | V42: 0.33141245 | W42: 0.23030727 | X42: 0.28549064 | Y42: 0.1639088 | Z42: 0.018758579 | AA42: 0.043168824 | AB42: 0.11111111 | AC42: 0.14260555 | AD42: =VLOOKUP(B:B,库存明细报表10.16!L:P,5,0) -> 0 | AE42: =VLOOKUP(B:B,库存明细报表10.16!L:Q,6,0) -> 0 | AF42: =VLOOKUP(B:B,库存明细报表10.16!L:T,9,0) -> 40 | AG42: =VLOOKUP(A:A,进销存报表10.16!A:J,10,0) -> 1 | AH42: =VLOOKUP(A:A,进销存报表10.16!A:K,11,0) -> 36 | AI42: 72.93 | AJ42: 60.29 | AK42: 0.67 | AL42: 9.6666667 | AM42: =AK42/AI42 -> 0.0091868915 | AN42: =AL42/AJ42 -> 0.16033615
A43: OO2EWP06600 | B43: B0GWQY1VKB | C43: 8525EWP0665US | D43: FBA | E43: 维稳 | F43: 老品 | G43: 潜力 | H43: 潜力 | I43: 瘦狗 | J43: 26.99 | K43: 21.08 | L43: 24.54 | M43: 22.08 | N43: 26.99 | O43: 0 | P43: 4 | Q43: 0 | R43: 3 | S43: 1 | T43: 9 | U43: 2 | V43: 0.20781505 | W43: 0.21657343 | X43: 0.23684707 | Y43: 0 | Z43: 0.028860527 | AA43: 0.070511208 | AB43: 0.20930233 | AC43: 0.23026062 | AD43: =VLOOKUP(B:B,库存明细报表10.16!L:P,5,0) -> 11 | AE43: =VLOOKUP(B:B,库存明细报表10.16!L:Q,6,0) -> 11 | AF43: =VLOOKUP(B:B,库存明细报表10.16!L:T,9,0) -> 0 | AG43: =VLOOKUP(A:A,进销存报表10.16!A:J,10,0) -> 23 | AH43: =VLOOKUP(A:A,进销存报表10.16!A:K,11,0) -> 9 | AI43: 127.73 | AJ43: 97.31 | AK43: 1.33 | AL43: 4.3333333 | AM43: =AK43/AI43 -> 0.010412589 | AN43: =AL43/AJ43 -> 0.044531223
...

Sheet 日更监控
A1: 更新时间 | B1: 商编 | C1: ASIN | D1: 分组 | E1: 开始推广月份 | F1: 状态 | G1: 近7日 | H1: 前7日 | I1: 环比% | J1: 日均 | K1: FBA可用 | L1: FBA在途 | M1: 海外仓可用 | N1: 海外仓在途 | O1: 本地仓可用 | P1: 采购在途 | Q1: 全链路库存 | R1: 库销比(月)※ | S1: FBA可售天数 | T1: 9月累计 | U1: 月目标 | V1: 达成率% | W1: 目标进度% | X1: 10%市占月目标 | Y1: 近30日销量(FBA) | Z1: 近30日销量(全渠道) | AA1: 10%目标达成% | AB1: 是否已完成10% | AC1: 上月销量 | AD1: 成交价$(折算) | AE1: 界面LP$ | AF1: 红线价$ | AG1: 价格下限$ | AH1: 价格上限$ | AI1: 可降幅度% | AJ1: 降到底毛利率% | AK1: 毛利率%(近30d FBA) | AL1: 促销费率% | AM1: 近30日PV | AN1: 转化率% | AO1: 前28日日均 | AP1: 诊断类型 | AQ1: 等级 | AR1: 改善动作 | AS1: DRI | AT1: 预警
A2: 2026-10-16 | B2: ⚠️ 本页由脚本每日自动覆盖刷新｜销量=FBA口径(该商编下发货模式=FBA的链接出库销量)｜库存=BI日终快照全渠道｜毛利率/成交价=BI损益明细(finance) ASIN级｜成交价=出库销售单价(￥)÷结算汇率6.70，已含coupon/促销｜库销比(月)※=全链路库存÷近30日销量(全渠道)
A3: 2026-10-16 | B3: OO2EWP00400 | C3: B0CKX9SK3Y | D3: 大组 | E3: 9月 | F3: 正常 | G3: 3.0 | H3: 4.0 | I3: -25.0 | J3: 0.43 | K3: 87 | L3: 60 | M3: 8 | N3: 27 | O3: 24 | P3: 120 | Q3: 326 | R3: 9.06 | S3: 203.0 | T3: 7.0 | U3: 15 | V3: 46.7 | W3: 53.3 | X3: 95 | Y3: 13.0 | Z3: 36.0 | AA3: 13.7 | AB3: 未完成 | AC3: 9.0 | AD3: 25.13 | AE3: 22.99 | AF3: 21.21 | AG3: 18.14 | AH3: 22.17 | AI3: 27.8 | AJ3: -10.9 | AK3: 19.9 | AL3: 8.0 | AM3: 581 | AN3: 2.24 | AO3: 0.39 | AP3: 高浏览低转化 | AQ3: P3 | AR3: 产品端：竞对与市场价格核查；运营端：看页面承接与评价 | AS3: 林心园
A4: 2026-10-16 | B4: OO2EWP01300 | C4: B0CKX85NSB | D4: 小组 | E4: — | F4: A-零销量 | G4: 0.0 | H4: 0.0 | J4: 0.0 | K4: 2 | L4: 35 | M4: 15 | N4: 64 | O4: 12 | P4: 128 | Q4: 256 | T4: 0.0 | U4: 12 | V4: 0.0 | W4: 53.3 | X4: 20 | Y4: 0.0 | Z4: 0.0 | AA4: 0.0 | AB4: 未完成 | AC4: 0.0 | AE4: 71.7 | AF4: 54.74 | AG4: 52.46 | AH4: 64.11 | AM4: 82 | AN4: 0.0 | AO4: 0.0 | AT4: ⚫近7日0销量 / 🎯进度落后(0%/53%)
A5: 2026-10-16 | B5: OO2EWP01600 | C5: B0CKX9959W | D5: 大组 | E5: — | F5: D-掉量 | G5: 1.0 | H5: 4.0 | I5: -75.0 | J5: 0.14 | K5: 44 | L5: 20 | M5: 52 | N5: 23 | O5: 29 | P5: 120 | Q5: 288 | R5: 19.2 | S5: 308.0 | T5: 6.0 | U5: 15 | V5: 40.0 | W5: 53.3 | X5: 33 | Y5: 12.0 | Z5: 15.0 | AA5: 36.4 | AB5: 未完成 | AC5: 16.0 | AD5: 25.91 | AE5: 22.07 | AF5: 19.39 | AG5: 19.66 | AH5: 24.03 | AI5: 24.1 | AJ5: 4.2 | AK5: 27.3 | AL5: 8.0 | AM5: 127 | AN5: 9.45 | AO5: 0.46 | AP5: 销量明显下降 | AQ5: P2 | AR5: 运营：查转化与价格、竞对；广告端：查投放是否缩减 | AS5: 林心园 | AT5: 🟡掉量-75%
A6: 2026-10-16 | B6: OO2EWP01800 | C6: B0HJ4NTDXG | D6: 大组 | E6: 9月 | F6: D-掉量 | G6: 1.0 | H6: 3.0 | I6: -66.7 | J6: 0.14 | K6: 4 | L6: 0 | M6: 8 | N6: 11 | O6: 16 | P6: 18 | Q6: 57 | R6: 8.14 | S6: 28.0 | T6: 4.0 | U6: 2 | V6: 200.0 | W6: 53.3 | X6: 26 | Y6: 7.0 | Z6: 7.0 | AA6: 26.9 | AB6: 未完成 | AC6: 4.0 | AD6: 48.01 | AE6: 42.31 | AF6: 42.15 | AG6: 34.59 | AH6: 42.28 | AI6: 28.0 | AJ6: -18.3 | AK6: 14.8 | AL6: 8.0 | AM6: 100 | AN6: 7.0 | AO6: 0.21 | AP6: 断货中风险 | AQ6: P1 | AR6: 运营：确认调价与节奏；供应链：确认最近一批到货时间与数量 | AS6: 林心园 | AT6: 🟡掉量-67%
A7: 2026-10-16 | B7: OO2EWP02000 | C7: B0CKX8PSXX | D7: 大组 | E7: 9月 | F7: D-掉量 | G7: 2.0 | H7: 5.0 | I7: -60.0 | J7: 0.29 | K7: 46 | L7: 20 | M7: 83 | N7: 59 | O7: 82 | P7: 240 | Q7: 530 | R7: 20.38 | S7: 161.0 | T7: 7.0 | U7: 7 | V7: 100.0 | W7: 53.3 | X7: 46 | Y7: 19.0 | Z7: 26.0 | AA7: 41.3 | AB7: 未完成 | AC7: 20.0 | AD7: 22.14 | AE7: 22.07 | AF7: 18.42 | AG7: 20.54 | AH7: 25.11 | AI7: 7.2 | AJ7: 7.7 | AK7: 14.4 | AL7: 7.6 | AM7: 525 | AN7: 3.62 | AO7: 0.71 | AP7: 销量明显下降 | AQ7: P2 | AR7: 运营：查转化与价格、竞对；广告端：查投放是否缩减 | AS7: 林心园 | AT7: 🟡掉量-60%
A8: 2026-10-16 | B8: OO2EWP02100 | C8: B0GWQY9RW4 | D8: 小组 | E8: — | F8: A-零销量 | G8: 0.0 | H8: 1.0 | I8: -100.0 | J8: 0.0 | K8: 5 | L8: 0 | M8: 18 | N8: 8 | O8: 35 | P8: 0 | Q8: 66 | R8: 16.5 | T8: 1.0 | U8: 3 | V8: 33.3 | W8: 53.3 | X8: 19 | Y8: 3.0 | Z8: 4.0 | AA8: 15.8 | AB8: 未完成 | AC8: 3.0 | AD8: 18.08 | AE8: 24.43 | AF8: 22.59 | AG8: 16.72 | AH8: 20.44 | AI8: 7.5 | AJ8: 24.5 | AK8: 30.2 | AL8: 0.0 | AM8: 47 | AN8: 6.38 | AO8: 0.11 | AP8: 低浏览高转化 | AQ8: P3 | AR8: 广告端：放量（加大投放/拓词） | AS8: 林心园 | AT8: ⚫近7日0销量 / 🟡掉量-100% / 🎯进度落后(33%/53%)
A9: 2026-10-16 | B9: OO2EWP03100 | C9: B0GWZNCP7S | D9: 小组 | E9: — | F9: A-零销量 | G9: 0.0 | H9: 0.0 | J9: 0.0 | K9: 9 | L9: 0 | M9: 8 | N9: 26 | O9: 12 | P9: 120 | Q9: 175 | R9: 43.75 | T9: 0.0 | U9: 4 | V9: 0.0 | W9: 53.3 | X9: 16 | Y9: 0.0 | Z9: 4.0 | AA9: 0.0 | AB9: 未完成 | AC9: 0.0 | AE9: 35.87 | AF9: 32.05 | AG9: 34.19 | AH9: 41.79 | AM9: 51 | AN9: 0.0 | AO9: 0.0 | AP9: 滞销风险 | AQ9: P1 | AR9: 运营+推广：促销/降价换量；供应链：缩减海外仓发货计划 | AS9: 林心园 | AT9: ⚫近7日0销量 / 🎯进度落后(0%/53%)
A10: 2026-10-16 | B10: OO2EWP04700 | C10: B0GWZLNY3H | D10: 小组 | E10: 9月 | F10: B-断货风险 | G10: 1.0 | H10: 0.0 | J10: 0.14 | K10: 0 | L10: 0 | M10: 5 | N10: 24 | O10: 56 | P10: 96 | Q10: 181 | R10: 36.2 | S10: 0.0 | T10: 1.0 | U10: 2 | V10: 50.0 | W10: 53.3 | X10: 4 | Y10: 5.0 | Z10: 5.0 | AA10: 125.0 | AB10: ✅ 已完成 | AC10: 10.0 | AD10: 20.39 | AE10: 46.99 | AF10: 35.67 | AG10: 40.76 | AH10: 49.81 | AI10: -99.9 | AK10: 33.2 | AL10: 0.0 | AM10: 126 | AN10: 3.97 | AO10: 0.21 | AP10: 断货高风险 | AQ10: P0 | AR10: 运营：调价控销；供应链：海外仓发货加倍 + 同步最近一批到货时间 | AS10: 林心园 | AT10: 🔴断货风险(0.0天)
A11: 2026-10-16 | B11: OO2EWP05000 | C11: B0GWZKWRT4 | D11: 小组 | E11: 9月 | F11: B-断货风险 | G11: 6.0 | H11: 2.0 | I11: 200.0 | J11: 0.86 | K11: 4 | L11: 0 | M11: 0 | N11: 0 | O11: 14 | P11: 40 | Q11: 58 | R11: 3.41 | S11: 4.7 | T11: 9.0 | U11: 3 | V11: 300.0 | W11: 53.3 | X11: 9 | Y11: 17.0 | Z11: 17.0 | AA11: 188.9 | AB11: ✅ 已完成 | AC11: 9.0 | AD11: 22.88 | AE11: 21.15 | AF11: 20.85 | AG11: 15.81 | AH11: 19.33 | AI11: 30.9 | AJ11: -43.4 | AK11: 0.9 | AL11: 6.7 | AM11: 82 | AN11: 20.73 | AO11: 0.46 | AP11: 断货高风险 | AQ11: P0 | AR11: 运营：控销节奏、暂停加码；供应链：确认在途批量与到货时间 | AS11: 林心园 | AT11: 🔴断货风险(4.7天)
A12: 2026-10-16 | B12: OO2EWP05800 | C12: B0G3LJYFZX | D12: 小组 | E12: 9月 | F12: 正常 | G12: 2.0 | H12: 2.0 | I12: 0.0 | J12: 0.29 | K12: 46 | L12: 4 | M12: 44 | N12: 24 | O12: 98 | P12: 0 | Q12: 216 | R12: 14.4 | S12: 161.0 | T12: 5.0 | U12: 4 | V12: 125.0 | W12: 53.3 | X12: 7 | Y12: 10.0 | Z12: 15.0 | AA12: 142.9 | AB12: ✅ 已完成 | AC12: 9.0 | AD12: 52.91 | AE12: 45.99 | AF12: 43.65 | AG12: 45.97 | AH12: 56.19 | AI12: 13.1 | AJ12: 14.2 | AK12: 25.5 | AL12: 7.2 | AM12: 166 | AN12: 6.02 | AO12: 0.32
A13: 2026-10-16 | B13: OO2EWP05900 | C13: B0GWQLN3LT | D13: 小组 | E13: — | F13: A-零销量 | G13: 0.0 | H13: 0.0 | J13: 0.0 | K13: 24 | L13: 40 | M13: 1 | N13: 36 | O13: 34 | P13: 0 | Q13: 135 | R13: 45.0 | T13: 0.0 | U13: 8 | V13: 0.0 | W13: 53.3 | X13: 8 | Y13: 1.0 | Z13: 3.0 | AA13: 12.5 | AB13: 未完成 | AC13: 7.0 | AD13: 43.63 | AE13: 42.99 | AF13: 31.01 | AG13: 30.86 | AH13: 37.71 | AI13: 29.3 | AJ13: 14.0 | AK13: 39.2 | AL13: 0.0 | AM13: 91 | AN13: 1.1 | AO13: 0.07 | AP13: 滞销风险 | AQ13: P1 | AR13: 运营+推广：促销/降价换量；供应链：缩减海外仓发货计划 | AS13: 林心园 | AT13: ⚫近7日0销量 / 🎯进度落后(0%/53%)
A14: 2026-10-16 | B14: OO2EWP06000 | C14: B0GWQFSGVJ | D14: 小组 | E14: — | F14: F-进度落后 | G14: 2.0 | H14: 0.0 | J14: 0.29 | K14: 43 | L14: 20 | M14: 23 | N14: 5 | O14: 0 | P14: 100 | Q14: 191 | R14: 63.67 | S14: 150.5 | T14: 2.0 | U14: 12 | V14: 16.7 | W14: 53.3 | X14: 10 | Y14: 3.0 | Z14: 3.0 | AA14: 30.0 | AB14: 未完成 | AC14: 7.0 | AD14: 20.03 | AE14: 24.43 | AF14: 18.98 | AG14: 20.24 | AH14: 24.74 | AI14: -1.1 | AK14: 37.8 | AL14: 5.6 | AM14: 67 | AN14: 4.48 | AO14: 0.07 | AT14: 🎯进度落后(17%/53%)
A15: 2026-10-16 | B15: OO2EWP06100 | C15: B0GWZG6T4W | D15: 小组 | E15: — | F15: F-进度落后 | G15: 1.0 | H15: 0.0 | J15: 0.14 | K15: 4 | L15: 2 | M15: 5 | N15: 16 | O15: 52 | P15: 0 | Q15: 79 | R15: 7.9 | S15: 28.0 | T15: 1.0 | U15: 5 | V15: 20.0 | W15: 53.3 | X15: 1 | Y15: 6.0 | Z15: 10.0 | AA15: 600.0 | AB15: ✅ 已完成 | AC15: 8.0 | AD15: 27.06 | AE15: 31.99 | AF15: 23.41 | AG15: 49.46 | AH15: 60.46 | AI15: -82.8 | AK15: 23.2 | AL15: 2.8 | AM15: 87 | AN15: 6.9 | AO15: 0.21 | AP15: 断货中风险 | AQ15: P1 | AR15: 运营：确认调价与节奏；供应链：确认最近一批到货时间与数量 | AS15: 林心园 | AT15: 🎯进度落后(20%/53%)
A16: 2026-10-16 | B16: OO2EWP06600 | C16: B0GWQY1VKB | D16: 小组 | E16: 9月 | F16: 正常 | G16: 2.0 | H16: 0.0 | J16: 0.29 | K16: 11 | L16: 0 | M16: 23 | N16: 9 | O16: 45 | P16: 80 | Q16: 168 | R16: 33.6 | S16: 38.5 | T16: 2.0 | U16: 3 | V16: 66.7 | W16: 53.3 | X16: 13 | Y16: 5.0 | Z16: 5.0 | AA16: 38.5 | AB16: 未完成 | AC16: 9.0 | AD16: 28.45 | AE16: 26.67 | AF16: 21.08 | AG16: 22.08 | AH16: 26.99 | AI16: 22.4 | AJ16: 4.2 | AK16: 25.6 | AL16: 7.3 | AM16: 61 | AN16: 8.2 | AO16: 0.14
A17: 2026-10-16 | B17: OO2EWP06700 | C17: B0GWQWCMPT | D17: 小组 | E17: — | F17: F-进度落后 | G17: 2.0 | H17: 1.0 | I17: 100.0 | J17: 0.29 | K17: 28 | L17: 23 | M17: 35 | N17: 14 | O17: 76 | P17: 60 | Q17: 236 | R17: 33.71 | S17: 98.0 | T17: 3.0 | U17: 15 | V17: 20.0 | W17: 53.3 | X17: 11 | Y17: 6.0 | Z17: 7.0 | AA17: 54.5 | AB17: 未完成 | AC17: 11.0 | AD17: 23.16 | AE17: 25.37 | AF17: 20.24 | AG17: 22.15 | AH17: 27.07 | AI17: 4.4 | AJ17: 14.8 | AK17: 18.5 | AL17: 3.1 | AM17: 67 | AN17: 8.96 | AO17: 0.29 | AT17: 🎯进度落后(20%/53%)
A18: 2026-10-16 | B18: OO2EWP07000 | C18: B0G3LHFPHD | D18: 大组 | E18: 9月 | F18: D-掉量 | G18: 1.0 | H18: 2.0 | I18: -50.0 | J18: 0.14 | K18: 31 | L18: 0 | M18: 5 | N18: 13 | O18: 27 | P18: 100 | Q18: 176 | R18: 14.67 | S18: 217.0 | T18: 3.0 | U18: 12 | V18: 25.0 | W18: 53.3 | X18: 21 | Y18: 4.0 | Z18: 12.0 | AA18: 19.0 | AB18: 未完成 | AC18: 4.0 | AD18: 24.08 | AE18: 22.07 | AF18: 18.44 | AG18: 20.51 | AH18: 25.07 | AI18: 14.8 | AJ18: 9.2 | AK18: 22.6 | AL18: 8.0 | AM18: 143 | AN18: 2.8 | AO18: 0.14 | AP18: 高浏览低转化 | AQ18: P3 | AR18: 产品端：竞对与市场价格核查；运营端：看页面承接与评价 | AS18: 林心园 | AT18: 🟡掉量-50% / 🎯进度落后(25%/53%)
A19: 2026-10-16 | B19: OO2EWP08100 | C19: B0DSW8VBT5 | D19: 小组 | E19: 9月 | F19: 正常 | G19: 4.0 | H19: 5.0 | I19: -20.0 | J19: 0.57 | K19: 12 | L19: 7 | M19: 53 | N19: 28 | O19: 54 | P19: 140 | Q19: 294 | R19: 11.76 | S19: 21.0 | T19: 13.0 | U19: 4 | V19: 325.0 | W19: 53.3 | X19: 12 | Y19: 20.0 | Z19: 25.0 | AA19: 166.7 | AB19: ✅ 已完成 | AC19: 14.0 | AD19: 29.09 | AE19: 29.43 | AF19: 23.39 | AG19: 23.08 | AH19: 28.2 | AI19: 20.7 | AJ19: -2.1 | AK19: 19.0 | AL19: 7.5 | AM19: 195 | AN19: 10.26 | AO19: 0.61 | AP19: 断货中风险 | AQ19: P1 | AR19: 运营：确认调价与节奏；供应链：确认最近一批到货时间与数量 | AS19: 林心园
A20: 2026-10-16 | B20: OO2EWP08200 | C20: B0GWQRW5DS | D20: 小组 | E20: — | F20: A-零销量 | G20: 0.0 | H20: 0.0 | J20: 0.0 | K20: 20 | L20: 20 | M20: 14 | N20: 83 | O20: 1 | P20: 0 | Q20: 138 | R20: 69.0 | T20: 0.0 | U20: 5 | V20: 0.0 | W20: 53.3 | X20: 8 | Y20: 0.0 | Z20: 2.0 | AA20: 0.0 | AB20: 未完成 | AC20: 0.0 | AE20: 32.16 | AF20: 20.32 | AG20: 29.91 | AH20: 36.56 | AM20: 59 | AN20: 0.0 | AO20: 0.0 | AP20: 滞销风险 | AQ20: P1 | AR20: 运营+推广：促销/降价换量；供应链：缩减海外仓发货计划 | AS20: 林心园 | AT20: ⚫近7日0销量 / 🎯进度落后(0%/53%)
A21: 2026-10-16 | B21: OO2EWP08400 | C21: B0GWZRG6FQ | D21: 小组 | E21: — | F21: F-进度落后 | G21: 1.0 | H21: 0.0 | J21: 0.14 | K21: 35 | L21: 20 | M21: 11 | N21: 28 | O21: 23 | P21: 120 | Q21: 237 | R21: 11.85 | S21: 245.0 | T21: 2.0 | U21: 11 | V21: 18.2 | W21: 53.3 | X21: 18 | Y21: 8.0 | Z21: 20.0 | AA21: 44.4 | AB21: 未完成 | AC21: 11.0 | AD21: 25.96 | AE21: 22.99 | AF21: 20.43 | AG21: 19.12 | AH21: 23.37 | AI21: 26.4 | AJ21: 2.3 | AK21: 28.0 | AL21: 7.5 | AM21: 147 | AN21: 5.44 | AO21: 0.36 | AP21: 销量明显下降 | AQ21: P2 | AR21: 运营：查转化与价格、竞对；广告端：查投放是否缩减 | AS21: 林心园 | AT21: 🎯进度落后(18%/53%)
A22: 2026-10-16 | B22: OO2EWP08500 | C22: B0GWQX2NTR | D22: 小组 | E22: — | F22: F-进度落后 | G22: 3.0 | H22: 1.0 | I22: 200.0 | J22: 0.43 | K22: 21 | L22: 1 | M22: 18 | N22: 0 | O22: 33 | P22: 32 | Q22: 105 | R22: 17.5 | S22: 49.0 | T22: 4.0 | U22: 11 | V22: 36.4 | W22: 53.3 | X22: 7 | Y22: 5.0 | Z22: 6.0 | AA22: 71.4 | AB22: 未完成 | AC22: 4.0 | AD22: 29.73 | AE22: 26.67 | AF22: 21.48 | AG22: 25.32 | AH22: 30.95 | AI22: 14.8 | AJ22: 15.0 | AK22: 27.6 | AL22: 8.0 | AM22: 80 | AN22: 6.25 | AO22: 0.14 | AT22: 🎯进度落后(36%/53%)
A23: 2026-10-16 | B23: OO2EWP08600 | C23: B0GWQTZDGZ | D23: 小组 | E23: 9月 | F23: D-掉量 | G23: 1.0 | H23: 4.0 | I23: -75.0 | J23: 0.14 | K23: 19 | L23: 2 | M23: 21 | N23: 10 | O23: 22 | P23: 84 | Q23: 158 | R23: 14.36 | S23: 133.0 | T23: 5.0 | U23: 6 | V23: 83.3 | W23: 53.3 | X23: 11 | Y23: 7.0 | Z23: 11.0 | AA23: 63.6 | AB23: 未完成 | AC23: 8.0 | AD23: 54.21 | AE23: 49.67 | AF23: 45.43 | AG23: 41.88 | AH23: 51.19 | AI23: 22.7 | AJ23: 3.3 | AK23: 25.3 | AL23: 8.0 | AM23: 120 | AN23: 5.83 | AO23: 0.25 | AT23: 🟡掉量-75%
A24: 2026-10-16 | B24: OO2EWP08700 | C24: B0GWZLNVH8 | D24: 小组 | E24: 9月 | F24: F-进度落后 | G24: 1.0 | H24: 0.0 | J24: 0.14 | K24: 10 | L24: 0 | M24: 4 | N24: 2 | O24: 17 | P24: 35 | Q24: 68 | R24: 11.33 | S24: 70.0 | T24: 1.0 | U24: 3 | V24: 33.3 | W24: 53.3 | X24: 3 | Y24: 5.0 | Z24: 6.0 | AA24: 166.7 | AB24: ✅ 已完成 | AC24: 5.0 | AD24: 26.3 | AE24: 23.91 | AF24: 20.13 | AG24: 23.22 | AH24: 28.38 | AI24: 11.7 | AJ24: 34.0 | AK24: 41.7 | AL24: 8.0 | AM24: 49 | AN24: 10.2 | AO24: 0.14 | AP24: 低浏览高转化 | AQ24: P3 | AR24: 广告端：放量（加大投放/拓词） | AS24: 林心园 | AT24: 🎯进度落后(33%/53%)
A25: 2026-10-16 | B25: OO2EWP08900 | C25: B0GWQNW9QC | D25: 小组 | E25: 9月 | F25: A-零销量 | G25: 0.0 | H25: 0.0 | J25: 0.0 | K25: 11 | L25: 2 | M25: 21 | N25: 1 | O25: 29 | P25: 20 | Q25: 84 | R25: 42.0 | T25: 1.0 | U25: 3 | V25: 33.3 | W25: 53.3 | X25: 16 | Y25: 1.0 | Z25: 2.0 | AA25: 6.2 | AB25: 未完成 | AC25: 2.0 | AD25: 24.99 | AE25: 22.99 | AF25: 19.05 | AG25: 21.59 | AH25: 26.39 | AI25: 13.6 | AJ25: 7.8 | AK25: 20.3 | AL25: 8.0 | AM25: 46 | AN25: 2.17 | AO25: 0.04 | AP25: 滞销风险 | AQ25: P1 | AR25: 运营+推广：促销/降价换量；供应链：缩减海外仓发货计划 | AS25: 林心园 | AT25: ⚫近7日0销量 / 🎯进度落后(33%/53%)
A26: 2026-10-16 | B26: OO2EWP10400 | C26: B0GWQKHTNJ | D26: 小组 | E26: 9月 | F26: 正常 | G26: 3.0 | H26: 4.0 | I26: -25.0 | J26: 0.43 | K26: 9 | L26: 0 | M26: 0 | N26: 59 | O26: 21 | P26: 156 | Q26: 245 | R26: 15.31 | S26: 21.0 | T26: 8.0 | U26: 3 | V26: 266.7 | W26: 53.3 | X26: 13 | Y26: 11.0 | Z26: 16.0 | AA26: 84.6 | AB26: 未完成 | AC26: 8.0 | AD26: 33.76 | AE26: 34.03 | AF26: 26.05 | AG26: 33.22 | AH26: 40.6 | AI26: 1.6 | AJ26: 31.5 | AK26: 32.6 | AL26: 7.4 | AM26: 100 | AN26: 11.0 | AO26: 0.29 | AP26: 断货中风险 | AQ26: P1 | AR26: 运营：确认调价与节奏；供应链：确认最近一批到货时间与数量 | AS26: 林心园
A27: 2026-10-16 | B27: OO2EWP11900 | C27: B0GWZH2JVV | D27: 小组 | E27: — | F27: 正常 | G27: 2.0 | H27: 0.0 | J27: 0.29 | K27: 6 | L27: 0 | M27: 1 | N27: 23 | O27: 21 | P27: 18 | Q27: 69 | R27: 7.67 | S27: 21.0 | T27: 2.0 | U27: 4 | V27: 50.0 | W27: 53.3 | X27: 6 | Y27: 8.0 | Z27: 9.0 | AA27: 133.3 | AB27: ✅ 已完成 | AC27: 6.0 | AD27: 58.74 | AE27: 59.79 | AF27: 54.13 | AG27: 49.3 | AH27: 60.25 | AI27: 16.1 | AJ27: -3.7 | AK27: 12.9 | AL27: 9.0 | AM27: 60 | AN27: 13.33 | AO27: 0.21 | AP27: 断货中风险 | AQ27: P1 | AR27: 运营：确认调价与节奏；供应链：确认最近一批到货时间与数量 | AS27: 林心园
A28: 2026-10-16 | B28: OO2EWP12000 | C28: B0GWQSPYL6 | D28: 小组 | E28: 9月 | F28: A-零销量 | G28: 0.0 | H28: 1.0 | I28: -100.0 | J28: 0.0 | K28: 31 | L28: 17 | M28: 15 | N28: 13 | O28: 35 | P28: 0 | Q28: 111 | R28: 22.2 | T28: 1.0 | U28: 2 | V28: 50.0 | W28: 53.3 | X28: 5 | Y28: 1.0 | Z28: 5.0 | AA28: 20.0 | AB28: 未完成 | AC28: 1.0 | AD28: 29.99 | AE28: 26.67 | AF28: 22.42 | AG28: 25.52 | AH28: 31.19 | AI28: 14.9 | AJ28: 5.8 | AK28: 19.8 | AL28: 8.0 | AM28: 87 | AN28: 1.15 | AO28: 0.04 | AP28: 滞销风险 | AQ28: P1 | AR28: 运营+推广：促销/降价换量；供应链：缩减海外仓发货计划 | AS28: 林心园 | AT28: ⚫近7日0销量 / 🟡掉量-100%
A29: 2026-10-16 | B29: OO2EWP12500 | C29: B0FC5MCKB1 | D29: 小组 | E29: — | F29: A-零销量 | G29: 0.0 | H29: 0.0 | J29: 0.0 | K29: 0 | L29: 0 | M29: 11 | N29: 2 | O29: 1 | P29: 24 | Q29: 38 | R29: 7.6 | T29: 0.0 | U29: 1 | V29: 0.0 | W29: 53.3 | X29: 2 | Y29: 0.0 | Z29: 5.0 | AA29: 0.0 | AB29: 未完成 | AC29: 0.0 | AE29: 33.29 | AF29: 16.23 | AM29: 24 | AN29: 0.0 | AO29: 0.0 | AT29: ⚫近7日0销量 / 🎯进度落后(0%/53%)
A30: 2026-10-16 | B30: ZC2CLK02000 | C30: B0DG2D424T | D30: 小组 | E30: — | F30: A-零销量 | G30: 0.0 | H30: 0.0 | J30: 0.0 | K30: 1 | L30: 1 | M30: 14 | N30: 10 | O30: 31 | P30: 20 | Q30: 77 | R30: 77.0 | T30: 0.0 | U30: 2 | V30: 0.0 | W30: 53.3 | X30: 9 | Y30: 0.0 | Z30: 1.0 | AA30: 0.0 | AB30: 未完成 | AC30: 0.0 | AE30: 29.99 | AF30: 21.64 | AG30: 18.16 | AH30: 22.2 | AM30: 13 | AN30: 0.0 | AO30: 0.0 | AP30: 滞销风险 | AQ30: P1 | AR30: 运营+推广：促销/降价换量；供应链：缩减海外仓发货计划 | AS30: 林心园 | AT30: ⚫近7日0销量 / 🎯进度落后(0%/53%)
A31: 2026-10-16 | B31: ZC2CLK04900 | C31: B0GWQVBRBB | D31: 小组 | E31: 9月 | F31: A-零销量 | G31: 0.0 | H31: 0.0 | J31: 0.0 | K31: 15 | L31: 0 | M31: 19 | N31: 12 | O31: 67 | P31: 20 | Q31: 133 | R31: 22.17 | T31: 1.0 | U31: 3 | V31: 33.3 | W31: 53.3 | X31: 14 | Y31: 1.0 | Z31: 6.0 | AA31: 7.1 | AB31: 未完成 | AC31: 3.0 | AD31: 38.99 | AE31: 35.87 | AF31: 22.2 | AG31: 35.05 | AH31: 42.84 | AI31: 10.1 | AJ31: 31.4 | AK31: 38.3 | AL31: 8.0 | AM31: 113 | AN31: 0.88 | AO31: 0.04 | AP31: 滞销风险 | AQ31: P1 | AR31: 运营+推广：促销/降价换量；供应链：缩减海外仓发货计划 | AS31: 林心园 | AT31: ⚫近7日0销量 / 🎯进度落后(33%/53%)
A32: 2026-10-16 | B32: ZC2CLK05300 | C32: B0GWR5G1FG | D32: 小组 | E32: — | F32: A-零销量 | G32: 0.0 | H32: 0.0 | J32: 0.0 | K32: 34 | L32: 18 | M32: 36 | N32: 7 | O32: 60 | P32: 60 | Q32: 215 | R32: 23.89 | T32: 0.0 | U32: 10 | V32: 0.0 | W32: 53.3 | X32: 13 | Y32: 3.0 | Z32: 9.0 | AA32: 23.1 | AB32: 未完成 | AC32: 14.0 | AD32: 35.9 | AE32: 44.15 | AF32: 36.03 | AG32: 33.2 | AH32: 40.58 | AI32: 7.5 | AJ32: -42.5 | AK32: -31.8 | AL32: 7.5 | AM32: 161 | AN32: 1.86 | AO32: 0.14 | AP32: 高浏览低转化 | AQ32: P3 | AR32: 产品端：竞对与市场价格核查；运营端：看页面承接与评价 | AS32: 林心园 | AT32: ⚫近7日0销量 / 🎯进度落后(0%/53%)
A34: 【近14日销量矩阵】出库口径 | B34: 2026-10-03 | C34: 2026-10-04 | D34: 2026-10-05 | E34: 2026-10-06 | F34: 2026-10-07 | G34: 2026-10-08 | H34: 2026-10-09 | I34: 2026-10-10 | J34: 2026-10-11 | K34: 2026-10-12 | L34: 2026-10-13 | M34: 2026-10-14 | N34: 2026-10-15 | O34: 2026-10-16 | P34: 合计
A35: OO2EWP00400 | B35: B0CKX9SK3Y | C35: 1.0 | D35: 0.0 | E35: 1.0 | F35: 0.0 | G35: 1.0 | H35: 1.0 | I35: 0.0 | J35: 1.0 | K35: 0.0 | L35: 2.0 | M35: 0.0 | N35: 0.0 | O35: 0.0 | P35: 0.0 | Q35: 7.0
A36: OO2EWP01300 | B36: B0CKX85NSB | C36: 0.0 | D36: 0.0 | E36: 0.0 | F36: 0.0 | G36: 0.0 | H36: 0.0 | I36: 0.0 | J36: 0.0 | K36: 0.0 | L36: 0.0 | M36: 0.0 | N36: 0.0 | O36: 0.0 | P36: 0.0 | Q36: 0.0
A37: OO2EWP01600 | B37: B0CKX9959W | C37: 1.0 | D37: 0.0 | E37: 0.0 | F37: 2.0 | G37: 1.0 | H37: 0.0 | I37: 0.0 | J37: 0.0 | K37: 0.0 | L37: 1.0 | M37: 0.0 | N37: 0.0 | O37: 0.0 | P37: 0.0 | Q37: 5.0
A38: OO2EWP01800 | B38: B0HJ4NTDXG | C38: 0.0 | D38: 1.0 | E38: 1.0 | F38: 0.0 | G38: 1.0 | H38: 0.0 | I38: 0.0 | J38: 0.0 | K38: 0.0 | L38: 0.0 | M38: 0.0 | N38: 1.0 | O38: 0.0 | P38: 0.0 | Q38: 4.0
A39: OO2EWP02000 | B39: B0CKX8PSXX | C39: 0.0 | D39: 0.0 | E39: 0.0 | F39: 2.0 | G39: 2.0 | H39: 1.0 | I39: 0.0 | J39: 0.0 | K39: 0.0 | L39: 0.0 | M39: 1.0 | N39: 1.0 | O39: 0.0 | P39: 0.0 | Q39: 7.0
A40: OO2EWP02100 | B40: B0GWQY9RW4 | C40: 0.0 | D40: 0.0 | E40: 0.0 | F40: 0.0 | G40: 1.0 | H40: 0.0 | I40: 0.0 | J40: 0.0 | K40: 0.0 | L40: 0.0 | M40: 0.0 | N40: 0.0 | O40: 0.0 | P40: 0.0 | Q40: 1.0
A41: OO2EWP03100 | B41: B0GWZNCP7S | C41: 0.0 | D41: 0.0 | E41: 0.0 | F41: 0.0 | G41: 0.0 | H41: 0.0 | I41: 0.0 | J41: 0.0 | K41: 0.0 | L41: 0.0 | M41: 0.0 | N41: 0.0 | O41: 0.0 | P41: 0.0 | Q41: 0.0
...

Sheet 潜力
A1: 商品编码 | B1: PT品牌asin | C1: 平台商品编码 | D1: 发货方式 | E1: 平台SKU状态 | F1: 新/老品 | G1: Q2 bcg（asin） | H1: Q3 bcg（asin） | I1: bcg（商编维度） | J1: 当前界面list price | K1: 红线价 | L1: 中心价 | M1: 价格下限 | N1: 价格上限 | O1: 4月销量 | P1: 5月销量 | Q1: 6月销量 | R1: 7月销量 | S1: 8月销量 | T1: 9月销量 | U1: 10月销量（截至10.4） | V1: p1考核销量目标 | W1: 9月销量达标进度 | X1: Q2毛利率 | Y1: Q3毛利率 | Z1: 9月毛利率 | AA1: 9月退款率 | AB1: 9月广告费率 | AC1: 9月促销费率 | AD1: 9月转化率 | AE1: 9月广告转化率 | AF1: FBA可用 | AG1: FBA可售 | AH1: FBA在途 | AI1: 海外仓可用库存 | AJ1: 海外仓在途库存 | AK1: Q2市场月均销量 | AL1: Q3市场月均销量 | AM1: Q2月均销量 | AN1: Q3月均销量 | AO1: PT Q2asin市占 | AP1: PT Q3asin市占 | AQ1: 销量目标到10% | AR1: 202609目标 | AS1: 202610目标 | AT1: 202611目标 | AU1: 202612目标 | AV1: 202701目标 | AW1: 202702目标 | AX1: 分组（以组销200分界） | AY1: 开始推广月份 | AZ1: 链接质量检测得分 | BA1: 备注（实际执行情况）
A2: OO2EWP05800 | B2: B0G3LJYFZX | C2: 6114EWP058CUS | D2: FBA | E2: 维稳 | F2: 老品 | G2: 潜力 | H2: 明星 | I2: 明星 | J2: =49.99*0.92 -> 45.9908 | K2: 43.65 | L2: 51.08 | M2: 45.97 | N2: 56.19 | O2: 0 | P2: 3 | Q2: 12 | R2: 15 | S2: 3 | T2: 10 | U2: 4 | V2: 11 | W2: =T2/V2 -> 0.90909091 | X2: 0.243 | Y2: 0.20699482 | Z2: 0.39243854 | AA2: 0.10731844 | AB2: 0.021167429 | AC2: 0.040896758 | AD2: 0.14492754 | AE2: 0.11741438 | AF2: =_xlfn.XLOOKUP(B2,库存明细报表10.16!L:L,库存明细报表10.16!P:P) -> 46 | AG2: =_xlfn.XLOOKUP(B2,库存明细报表10.16!L:L,库存明细报表10.16!Q:Q) -> 38 | AH2: =_xlfn.XLOOKUP(B2,库存明细报表10.16!L:L,库存明细报表10.16!T:T) -> 4 | AI2: =VLOOKUP(A:A,进销存报表10.16!A:J,10,0) -> 44 | AJ2: =VLOOKUP(A:A,进销存报表10.16!A:K,11,0) -> 24 | AK2: 68.51 | AL2: 42.92 | AM2: 5.33 | AN2: 9 | AO2: =AM2/AK2 -> 0.077798861 | AP2: =AN2/AL2 -> 0.20969245 | AQ2: =ROUNDUP(AK2*10%,0) -> 7 | AR2: 4 | AS2: 6 | AT2: =AS2*1.5 -> 9 | AU2: 11 | AV2: 12 | AW2: 15 | AX2: 小组 | AY2: 9月 | AZ2: =VLOOKUP(B:B,链接质量检测!A:V,22,0) -> 97 | BA2: 8月下滑-8月初即将断货，降低促销后销量下滑
A3: OO2EWP07000 | B3: B0G3LHFPHD | C3: 7009EWP070JUS | D3: FBA | E3: 维稳 | F3: 老品 | G3: 潜力 | H3: 瘦狗 | I3: 潜力 | J3: =23.99*0.92 -> 22.0708 | K3: 18.44 | L3: 22.79 | M3: 20.51 | N3: 25.07 | O3: 0 | P3: 4 | Q3: 4 | R3: 18 | S3: 10 | T3: 2 | U3: 3 | V3: 16 | W3: =T3/V3 -> 0.125 | X3: 0.216 | Y3: 0.14171206 | Z3: -0.18193169 | AA3: 0.32199459 | AB3: 0.17575055 | AC3: 0.056392115 | AD3: 0.035714286 | AE3: 0.10234494 | AF3: =_xlfn.XLOOKUP(B3,库存明细报表10.16!L:L,库存明细报表10.16!P:P) -> 31 | AG3: =_xlfn.XLOOKUP(B3,库存明细报表10.16!L:L,库存明细报表10.16!Q:Q) -> 14 | AH3: =_xlfn.XLOOKUP(B3,库存明细报表10.16!L:L,库存明细报表10.16!T:T) -> 0 | AI3: =VLOOKUP(A:A,进销存报表10.16!A:J,10,0) -> 5 | AJ3: =VLOOKUP(A:A,进销存报表10.16!A:K,11,0) -> 13 | AK3: 201.99 | AL3: 119.35 | AM3: 2.67 | AN3: 11 | AO3: =AM3/AK3 -> 0.013218476 | AP3: =AN3/AL3 -> 0.092165899 | AQ3: =ROUNDUP(AK3*10%,0) -> 21 | AR3: 12 | AS3: 12 | AT3: 15 | AU3: 16 | AV3: 17 | AW3: 21 | AX3: 大组 | AY3: 9月 | AZ3: =VLOOKUP(B:B,链接质量检测!A:V,22,0) -> 97 | BA3: 8月下滑-8月库存不足有小幅涨价，期间coupon中断过
A4: OO2EWP02000 | B4: B0CKX8PSXX | C4: 2100EWP020ZUS | D4: FBA | E4: 维稳 | F4: 老品 | G4: 潜力 | H4: 瘦狗 | I4: 潜力 | J4: =23.99*0.92 -> 22.0708 | K4: 18.42 | L4: 22.83 | M4: 20.54 | N4: 25.11 | O4: 10 | P4: 6 | Q4: 21 | R4: 19 | S4: 7 | T4: 19 | U4: 8 | V4: 28 | W4: =T4/V4 -> 0.67857143 | X4: 0.255 | Y4: 0.057603836 | Z4: -0.03076376 | AA4: 0.15626385 | AB4: 0.071610239 | AC4: 0.071021779 | AD4: 0.048969072 | AE4: 0.085500004 | AF4: =_xlfn.XLOOKUP(B4,库存明细报表10.16!L:L,库存明细报表10.16!P:P) -> 26 | AG4: =_xlfn.XLOOKUP(B4,库存明细报表10.16!L:L,库存明细报表10.16!Q:Q) -> 22 | AH4: =_xlfn.XLOOKUP(B4,库存明细报表10.16!L:L,库存明细报表10.16!T:T) -> 20 | AI4: =VLOOKUP(A:A,进销存报表10.16!A:J,10,0) -> 83 | AJ4: =VLOOKUP(A:A,进销存报表10.16!A:K,11,0) -> 59 | AK4: 452.27 | AL4: 324.08 | AM4: 9.67 | AN4: 18 | AO4: =AM4/AK4 -> 0.021381033 | AP4: =AN4/AL4 -> 0.055541842 | AQ4: =ROUNDUP(AK4*10%,0) -> 46 | AR4: 7 | AS4: 14 | AT4: 21 | AU4: 28 | AV4: 37 | AW4: 46 | AX4: 大组 | AY4: 9月 | AZ4: =VLOOKUP(B:B,链接质量检测!A:V,22,0) -> 97 | BA4: 6、7月份大多是PO出单，价格和利润相对较低，后期转FBA价格相对较高，销量有所下滑
A5: OO2EWP00400 | B5: B0CKX9SK3Y | C5: 8753EWP0043US | D5: FBA | E5: 维稳 | F5: 老品 | G5: 潜力 | H5: 瘦狗 | I5: 潜力 | J5: =24.99*0.92 -> 22.9908 | K5: 21.21 | L5: 20.15 | M5: 18.14 | N5: 22.17 | O5: 16 | P5: 10 | Q5: 10 | R5: 21 | S5: 7 | T5: 10 | U5: 7 | V5: 35 | W5: =T5/V5 -> 0.28571429 | X5: 0.235 | Y5: 0.1891784 | Z5: 0.074141481 | AA5: 0.10980346 | AB5: 0.11878702 | AC5: 0.068156981 | AD5: 0.029761905 | AE5: 0.065627557 | AF5: =_xlfn.XLOOKUP(B5,库存明细报表10.16!L:L,库存明细报表10.16!P:P) -> 47 | AG5: =_xlfn.XLOOKUP(B5,库存明细报表10.16!L:L,库存明细报表10.16!Q:Q) -> 46 | AH5: =_xlfn.XLOOKUP(B5,库存明细报表10.16!L:L,库存明细报表10.16!T:T) -> 60 | AI5: =VLOOKUP(A:A,进销存报表10.16!A:J,10,0) -> 8 | AJ5: =VLOOKUP(A:A,进销存报表10.16!A:K,11,0) -> 27 | AK5: 947.59 | AL5: 838.05 | AM5: 11.67 | AN5: 13.333333 | AO5: =AM5/AK5 -> 0.012315453 | AP5: =AN5/AL5 -> 0.01590995 | AQ5: =ROUNDUP(AK5*10%,0) -> 95 | AR5: 15 | AS5: 23 | AT5: 30 | AU5: 35 | AV5: 46 | AW5: 60 | AX5: 大组 | AY5: 9月 | AZ5: =VLOOKUP(B:B,链接质量检测!A:V,22,0) -> 97 | BA5: 7月底库存较低有进行过涨价操作，8月销量下滑，目前库存恢复
A6: OO2EWP01600 | B6: B0CKX9959W | C6: 8703EWP016ZUS | D6: FBA | E6: 维稳 | F6: 老品 | G6: 潜力 | H6: 潜力 | I6: 潜力 | J6: =23.99*0.92 -> 22.0708 | K6: 19.39 | L6: 21.84 | M6: 19.66 | N6: 24.03 | O6: 3 | P6: 4 | Q6: 3 | R6: 22 | S6: 20 | T6: 16 | U6: 5 | V6: 20 | W6: =T6/V6 -> 0.8 | X6: 0.297 | Y6: 0.2197321 | Z6: 0.23201475 | AA6: 0 | AB6: 0.046243748 | AC6: 0.083852331 | AD6: 0.12121212 | AE6: 0.10231112 | AF6: =_xlfn.XLOOKUP(B6,库存明细报表10.16!L:L,库存明细报表10.16!P:P) -> 44 | AG6: =_xlfn.XLOOKUP(B6,库存明细报表10.16!L:L,库存明细报表10.16!Q:Q) -> 17 | AH6: =_xlfn.XLOOKUP(B6,库存明细报表10.16!L:L,库存明细报表10.16!T:T) -> 20 | AI6: =VLOOKUP(A:A,进销存报表10.16!A:J,10,0) -> 52 | AJ6: =VLOOKUP(A:A,进销存报表10.16!A:K,11,0) -> 23 | AK6: 320.08 | AL6: 239.53 | AM6: 3.67 | AN6: 19.666667 | AO6: =AM6/AK6 -> 0.011465884 | AP6: =AN6/AL6 -> 0.082105234 | AQ6: =ROUNDUP(AK6*10%,0) -> 33 | AR6: 15 | AS6: 15 | AT6: 15 | AU6: 20 | AV6: 27 | AW6: 33 | AX6: 大组 | AZ6: =VLOOKUP(B:B,链接质量检测!A:V,22,0) -> 97
A7: OO2EWP08100 | B7: B0DSW8VBT5 | C7: 1753EWP081HUS | D7: FBA | E7: 维稳 | F7: 老品 | G7: 潜力 | H7: 明星 | I7: 潜力 | J7: =31.99*0.92 -> 29.4308 | K7: 23.39 | L7: 25.64 | M7: 23.08 | N7: 28.2 | O7: 0 | P7: 1 | Q7: 7 | R7: 7 | S7: 9 | T7: 17 | U7: 8 | V7: 10 | W7: =T7/V7 -> 1.7 | X7: 0.321 | Y7: 0.21564095 | Z7: 0.20614158 | AA7: 0 | AB7: 0.078417363 | AC7: 0.083846562 | AD7: 0.14049587 | AE7: 0.1187757 | AF7: =_xlfn.XLOOKUP(B7,库存明细报表10.16!L:L,库存明细报表10.16!P:P) -> 10 | AG7: =_xlfn.XLOOKUP(B7,库存明细报表10.16!L:L,库存明细报表10.16!Q:Q) -> 9 | AH7: =_xlfn.XLOOKUP(B7,库存明细报表10.16!L:L,库存明细报表10.16!T:T) -> 7 | AI7: =VLOOKUP(A:A,进销存报表10.16!A:J,10,0) -> 53 | AJ7: =VLOOKUP(A:A,进销存报表10.16!A:K,11,0) -> 28 | AK7: 110.96 | AL7: 52.31 | AM7: 2.67 | AN7: 10.333333 | AO7: =AM7/AK7 -> 0.024062725 | AP7: =AN7/AL7 -> 0.1975403 | AQ7: =ROUNDUP(AK7*10%,0) -> 12 | AR7: 4 | AS7: 5 | AT7: 6 | AU7: 8 | AV7: 10 | AW7: 12 | AX7: 小组 | AY7: 9月 | AZ7: =VLOOKUP(B:B,链接质量检测!A:V,22,0) -> 89
A8: OO2EWP08500 | B8: B0GWQX2NTR | C8: 9973EWP085JUS | D8: FBA | E8: 维稳 | F8: 老品 | G8: 潜力 | H8: 明星 | I8: 潜力 | J8: =28.99*0.92 -> 26.6708 | K8: 21.48 | L8: 28.14 | M8: 25.32 | N8: 30.95 | O8: 0 | P8: 2 | Q8: 2 | R8: 10 | S8: 8 | T8: 4 | U8: 4 | V8: 13 | W8: =T8/V8 -> 0.30769231 | X8: 0.358 | Y8: 0.27017427 | Z8: 0.3290419 | AA8: 0 | AB8: 0.053588441 | AC8: 0.083846994 | AD8: 0.11111111 | AE8: 0 | AF8: =_xlfn.XLOOKUP(B8,库存明细报表10.16!L:L,库存明细报表10.16!P:P) -> 8 | AG8: =_xlfn.XLOOKUP(B8,库存明细报表10.16!L:L,库存明细报表10.16!Q:Q) -> 8 | AH8: =_xlfn.XLOOKUP(B8,库存明细报表10.16!L:L,库存明细报表10.16!T:T) -> 1 | AI8: =VLOOKUP(A:A,进销存报表10.16!A:J,10,0) -> 18 | AJ8: =VLOOKUP(A:A,进销存报表10.16!A:K,11,0) -> 0 | AK8: 67.58 | AL8: 51.7 | AM8: 1.33 | AN8: 7.3333333 | AO8: =AM8/AK8 -> 0.019680379 | AP8: =AN8/AL8 -> 0.14184397 | AQ8: =ROUNDUP(AK8*10%,0) -> 7 | AR8: 11 | AS8: 11 | AT8: 12 | AU8: 13 | AV8: 14 | AW8: 15 | AX8: 小组 | AZ8: =VLOOKUP(B:B,链接质量检测!A:V,22,0) -> 97
A9: OO2EWP06100 | B9: B0GWZG6T4W | C9: 4365EWP061CUS | D9: FBA | E9: 维稳 | F9: 老品 | G9: 潜力 | H9: 金牛 | I9: 明星 | J9: =31.99 -> 31.99 | K9: 23.41 | L9: 54.96 | M9: 49.46 | N9: 60.46 | O9: 0 | P9: 1 | Q9: 0 | R9: 6 | S9: 4 | T9: 6 | U9: 2 | V9: 6 | W9: =T9/V9 -> 1 | X9: 0.225 | Y9: 0.10375858 | Z9: 0.2754715 | AA9: 0.13477452 | AB9: 0.042677824 | AC9: 0.045244127 | AD9: 0.18181818 | AE9: 0.24928278 | AF9: =_xlfn.XLOOKUP(B9,库存明细报表10.16!L:L,库存明细报表10.16!P:P) -> 2 | AG9: =_xlfn.XLOOKUP(B9,库存明细报表10.16!L:L,库存明细报表10.16!Q:Q) -> 2 | AH9: =_xlfn.XLOOKUP(B9,库存明细报表10.16!L:L,库存明细报表10.16!T:T) -> 2 | AI9: =VLOOKUP(A:A,进销存报表10.16!A:J,10,0) -> 5 | AJ9: =VLOOKUP(A:A,进销存报表10.16!A:K,11,0) -> 16 | AK9: 9.34 | AL9: 12.92 | AM9: 0.33 | AN9: 6.3333333 | AO9: =AM9/AK9 -> 0.035331906 | AP9: =AN9/AL9 -> 0.49019608 | AQ9: =ROUNDUP(AK9*10%,0) -> 1 | AR9: 5 | AS9: 5 | AT9: 6 | AU9: 6 | AV9: 7 | AW9: 7 | AX9: 小组 | AZ9: =VLOOKUP(B:B,链接质量检测!A:V,22,0) -> 81
A10: OO2EWP01800 | B10: B0HJ4NTDXG | C10: 4892EWP018PUS | D10: FBA | E10: 风险 | F10: 老品 | G10: 潜力 | H10: 瘦狗 | I10: 潜力 | J10: =45.99*0.92 -> 42.3108 | K10: 42.15 | L10: 38.44 | M10: 34.59 | N10: 42.28 | O10: 0 | P10: 2 | Q10: 3 | R10: 1 | S10: 0 | T10: 3 | U10: 3 | V10: #N/A | W10: =IF(T10>V10,"YES","NO") -> #N/A | X10: 0.222 | Y10: 0.06153889 | Z10: 0.13648205 | AA10: 0 | AB10: 0.050568643 | AC10: 0.08383781 | AD10: 0.15789474 | AE10: 0.13289077 | AF10: =_xlfn.XLOOKUP(B10,库存明细报表10.16!L:L,库存明细报表10.16!P:P) -> 4 | AG10: =_xlfn.XLOOKUP(B10,库存明细报表10.16!L:L,库存明细报表10.16!Q:Q) -> 3 | AH10: =_xlfn.XLOOKUP(B10,库存明细报表10.16!L:L,库存明细报表10.16!T:T) -> 0 | AI10: =VLOOKUP(A:A,进销存报表10.16!A:J,10,0) -> 8 | AJ10: =VLOOKUP(A:A,进销存报表10.16!A:K,11,0) -> 11 | AK10: 252.62 | AL10: 161.38 | AM10: 1.67 | AN10: 2 | AO10: =AM10/AK10 -> 0.0066107197 | AP10: =AN10/AL10 -> 0.012393109 | AQ10: =ROUNDUP(AK10*10%,0) -> 26 | AR10: 2 | AS10: 3 | AT10: 4 | AU10: 5 | AV10: 8 | AW10: 12 | AX10: 大组 | AY10: 9月 | AZ10: =VLOOKUP(B:B,链接质量检测!A:V,22,0) -> 89 | BA10: 8月初断货，目前刚到货，且库存较低
A11: OO2EWP03100 | B11: B0GWZNCP7S | C11: 6070EWP0315US | D11: FBA | E11: 维稳 | F11: 老品 | G11: 潜力 | H11: 瘦狗 | I11: 潜力 | J11: =38.99*0.92 -> 35.8708 | K11: 32.05 | L11: 37.99 | M11: 34.19 | N11: 41.79 | O11: 0 | P11: 0 | Q11: 1 | R11: 7 | S11: 2 | T11: 0 | U11: 1 | V11: 10 | W11: =T11/V11 -> 0 | X11: 0.231 | Y11: 0.16010831 | Z11: 0 | AA11: 0 | AB11: #DIV/0! | AC11: #DIV/0! | AD11: 0 | AE11: 0 | AF11: =_xlfn.XLOOKUP(B11,库存明细报表10.16!L:L,库存明细报表10.16!P:P) -> 9 | AG11: =_xlfn.XLOOKUP(B11,库存明细报表10.16!L:L,库存明细报表10.16!Q:Q) -> 0 | AH11: =_xlfn.XLOOKUP(B11,库存明细报表10.16!L:L,库存明细报表10.16!T:T) -> 0 | AI11: =VLOOKUP(A:A,进销存报表10.16!A:J,10,0) -> 8 | AJ11: =VLOOKUP(A:A,进销存报表10.16!A:K,11,0) -> 26 | AK11: 155.92 | AL11: 123.99 | AM11: 0.33 | AN11: 3.3333333 | AO11: =AM11/AK11 -> 0.00211647 | AP11: =AN11/AL11 -> 0.026883888 | AQ11: =ROUNDUP(AK11*10%,0) -> 16 | AR11: 4 | AS11: 5 | AT11: 8 | AU11: 10 | AV11: 13 | AW11: 16 | AX11: 小组 | AZ11: =VLOOKUP(B:B,链接质量检测!A:V,22,0) -> 97
A12: OO2EWP06600 | B12: B0GWQY1VKB | C12: 8525EWP0665US | D12: FBA | E12: 维稳 | F12: 老品 | G12: 潜力 | H12: 潜力 | I12: 瘦狗 | J12: =28.99*0.92 -> 26.6708 | K12: 21.08 | L12: 24.54 | M12: 22.08 | N12: 26.99 | O12: 0 | P12: 4 | Q12: 0 | R12: 3 | S12: 1 | T12: 9 | U12: 2 | V12: 10 | W12: =T12/V12 -> 0.9 | X12: 0.208 | Y12: 0.21657343 | Z12: 0.23684707 | AA12: 0 | AB12: 0.028860527 | AC12: 0.070511208 | AD12: 0.20930233 | AE12: 0.23026062 | AF12: =_xlfn.XLOOKUP(B12,库存明细报表10.16!L:L,库存明细报表10.16!P:P) -> 11 | AG12: =_xlfn.XLOOKUP(B12,库存明细报表10.16!L:L,库存明细报表10.16!Q:Q) -> 11 | AH12: =_xlfn.XLOOKUP(B12,库存明细报表10.16!L:L,库存明细报表10.16!T:T) -> 0 | AI12: =VLOOKUP(A:A,进销存报表10.16!A:J,10,0) -> 23 | AJ12: =VLOOKUP(A:A,进销存报表10.16!A:K,11,0) -> 9 | AK12: 127.73 | AL12: 97.31 | AM12: 1.33 | AN12: 4.3333333 | AO12: =AM12/AK12 -> 0.010412589 | AP12: =AN12/AL12 -> 0.044531223 | AQ12: =ROUNDUP(AK12*10%,0) -> 13 | AR12: 3 | AS12: 4 | AT12: 6 | AU12: 8 | AV12: 11 | AW12: 13 | AX12: 小组 | AY12: 9月 | AZ12: =VLOOKUP(B:B,链接质量检测!A:V,22,0) -> 97
A13: OO2EWP08600 | B13: B0GWQTZDGZ | C13: 4633EWP0866US | D13: FBA | E13: 维稳 | F13: 老品 | G13: 潜力 | H13: 瘦狗 | I13: 瘦狗 | J13: =53.99*0.92 -> 49.6708 | K13: 45.43 | L13: 46.54 | M13: 41.88 | N13: 51.19 | O13: 0 | P13: 1 | Q13: 0 | R13: 6 | S13: 5 | T13: 8 | U13: 6 | V13: 10 | W13: =T13/V13 -> 0.8 | X13: 0.275 | Y13: 0.19843972 | Z13: 0.18035891 | AA13: 0.25225266 | AB13: 0.023269959 | AC13: 0.051037269 | AD13: 0.15384615 | AE13: 0.15349244 | AF13: =_xlfn.XLOOKUP(B13,库存明细报表10.16!L:L,库存明细报表10.16!P:P) -> 17 | AG13: =_xlfn.XLOOKUP(B13,库存明细报表10.16!L:L,库存明细报表10.16!Q:Q) -> 6 | AH13: =_xlfn.XLOOKUP(B13,库存明细报表10.16!L:L,库存明细报表10.16!T:T) -> 2 | AI13: =VLOOKUP(A:A,进销存报表10.16!A:J,10,0) -> 21 | AJ13: =VLOOKUP(A:A,进销存报表10.16!A:K,11,0) -> 10 | AK13: 107.6 | AL13: 85.99 | AM13: 0.33 | AN13: 6.6666667 | AO13: =AM13/AK13 -> 0.0030669145 | AP13: =AN13/AL13 -> 0.077528395 | AQ13: =ROUNDUP(AK13*10%,0) -> 11 | AR13: 6 | AS13: 6 | AT13: 7 | AU13: 8 | AV13: 9 | AW13: 11 | AX13: 小组 | AY13: 9月 | AZ13: =VLOOKUP(B:B,链接质量检测!A:V,22,0) -> 97
